Workbook

Sheet 工作表1
A1: SO2 | B1: CO | C1: PM10 | D1: No2 | E1: O3 | F1: PM2.5 | J1: =MEDIAN(A:A) -> 2 | S1: MAD | U1: SO2 | V1: CO | W1: PM10 | X1: NO2 | Y1: O3 | Z1: PM2.5
A2: 5 | B2: 23 | C2: 49 | D2: 78 | E2: 35 | F2: 85 | J2: =MEDIAN(B:B) -> 3 | K2: =ABS(A2-$J$1) -> 3 | L2: =ABS(B2-$J$2) -> 20 | M2: =ABS(C2-$J$3) -> 26 | N2: =ABS(D2-$J$4) -> 55 | O2: =ABS(E2-$J$5) -> 5 | P2: =ABS(F2-$J$6) -> 47 | S2: =MEDIAN(K2:K24095) -> 2 | T2: SO2 | U2: =CORREL($A:$A,A:A) -> 1 | V2: =CORREL($A:$A,B:B) -> 0.20793915 | W2: =CORREL($A:$A,C:C) -> 0.26626195 | X2: =CORREL($A:$A,D:D) -> 0.26602225 | Y2: =CORREL($A:$A,E:E) -> 0.17722609 | Z2: =CORREL($A:$A,F:F) -> 0.28366856
A3: 8 | B3: 22 | C3: 51 | D3: 68 | E3: 33 | F3: 89 | J3: =MEDIAN(C:C) -> 23 | K3: =ABS(A3-$J$1) -> 6 | L3: =ABS(B3-$J$2) -> 19 | M3: =ABS(C3-$J$3) -> 28 | N3: =ABS(D3-$J$4) -> 45 | O3: =ABS(E3-$J$5) -> 7 | P3: =ABS(F3-$J$6) -> 51 | S3: =MEDIAN(L2:L24095) -> 1 | T3: CO | U3: =CORREL($B:$B,A:A) -> 0.20793915 | V3: =CORREL($B:$B,B:B) -> 1 | W3: =CORREL($B:$B,C:C) -> 0.47055828 | X3: =CORREL($B:$B,D:D) -> 0.73528034 | Y3: =CORREL($B:$B,E:E) -> 0.19676852 | Z3: =CORREL($B:$B,F:F) -> 0.59237894
A4: 57 | B4: 20 | C4: 42 | D4: 37 | E4: 11 | F4: 54 | J4: =MEDIAN(D:D) -> 23 | K4: =ABS(A4-$J$1) -> 55 | L4: =ABS(B4-$J$2) -> 17 | M4: =ABS(C4-$J$3) -> 19 | N4: =ABS(D4-$J$4) -> 14 | O4: =ABS(E4-$J$5) -> 29 | P4: =ABS(F4-$J$6) -> 16 | S4: =MEDIAN(M2:M24095) -> 9 | T4: PM10 | U4: =CORREL($C:$C,A:A) -> 0.26626195 | V4: =CORREL($C:$C,B:B) -> 0.47055828 | W4: =CORREL($C:$C,C:C) -> 1 | X4: =CORREL($C:$C,D:D) -> 0.34107521 | Y4: =CORREL($C:$C,E:E) -> 0.51268718 | Z4: =CORREL($C:$C,F:F) -> 0.86945087
A5: 2 | B5: 18 | C5: 63 | D5: 72 | E5: 22 | F5: 114 | J5: =MEDIAN(E:E) -> 40 | K5: =ABS(A5-$J$1) -> 0 | L5: =ABS(B5-$J$2) -> 15 | M5: =ABS(C5-$J$3) -> 40 | N5: =ABS(D5-$J$4) -> 49 | O5: =ABS(E5-$J$5) -> 18 | P5: =ABS(F5-$J$6) -> 76 | S5: =MEDIAN(N2:N24095) -> 10 | T5: NO2 | U5: =CORREL($D:$D,A:A) -> 0.26602225 | V5: =CORREL($D:$D,B:B) -> 0.73528034 | W5: =CORREL($D:$D,C:C) -> 0.34107521 | X5: =CORREL($D:$D,D:D) -> 1 | Y5: =CORREL($D:$D,E:E) -> 0.090471209 | Z5: =CORREL($D:$D,F:F) -> 0.43446792
A6: 2 | B6: 18 | C6: 46 | D6: 79 | E6: 32 | F6: 76 | J6: =MEDIAN(F:F) -> 38 | K6: =ABS(A6-$J$1) -> 0 | L6: =ABS(B6-$J$2) -> 15 | M6: =ABS(C6-$J$3) -> 23 | N6: =ABS(D6-$J$4) -> 56 | O6: =ABS(E6-$J$5) -> 8 | P6: =ABS(F6-$J$6) -> 38 | S6: =MEDIAN(O2:O24095) -> 9 | T6: O3 | U6: =CORREL($E:$E,A:A) -> 0.17722609 | V6: =CORREL($E:$E,B:B) -> 0.19676852 | W6: =CORREL($E:$E,C:C) -> 0.51268718 | X6: =CORREL($E:$E,D:D) -> 0.090471209 | Y6: =CORREL($E:$E,E:E) -> 1 | Z6: =CORREL($E:$E,F:F) -> 0.47716575
A7: 5 | B7: 18 | C7: 38 | D7: 57 | E7: 44 | F7: 84 | K7: =ABS(A7-$J$1) -> 3 | L7: =ABS(B7-$J$2) -> 15 | M7: =ABS(C7-$J$3) -> 15 | N7: =ABS(D7-$J$4) -> 34 | O7: =ABS(E7-$J$5) -> 4 | P7: =ABS(F7-$J$6) -> 46 | S7: =MEDIAN(P2:P24095) -> 18 | T7: PM2.5 | V7: =CORREL($F:$F,B:B) -> 0.59237894 | W7: =CORREL($F:$F,C:C) -> 0.86945087 | X7: =CORREL($F:$F,D:D) -> 0.43446792 | Y7: =CORREL($F:$F,E:E) -> 0.47716575 | Z7: =CORREL($F:$F,F:F) -> 1
A8: 5 | B8: 18 | C8: 32 | D8: 51 | E8: 50 | F8: 63 | K8: =ABS(A8-$J$1) -> 3 | L8: =ABS(B8-$J$2) -> 15 | M8: =ABS(C8-$J$3) -> 9 | N8: =ABS(D8-$J$4) -> 28 | O8: =ABS(E8-$J$5) -> 10 | P8: =ABS(F8-$J$6) -> 25
A9: 2 | B9: 17 | C9: 54 | D9: 7 | E9: 43 | F9: 23 | K9: =ABS(A9-$J$1) -> 0 | L9: =ABS(B9-$J$2) -> 14 | M9: =ABS(C9-$J$3) -> 31 | N9: =ABS(D9-$J$4) -> 16 | O9: =ABS(E9-$J$5) -> 3 | P9: =ABS(F9-$J$6) -> 15
A10: 8 | B10: 17 | C10: 52 | D10: 82 | E10: 19 | F10: 110 | K10: =ABS(A10-$J$1) -> 6 | L10: =ABS(B10-$J$2) -> 14 | M10: =ABS(C10-$J$3) -> 29 | N10: =ABS(D10-$J$4) -> 59 | O10: =ABS(E10-$J$5) -> 21 | P10: =ABS(F10-$J$6) -> 72
A11: 8 | B11: 17 | C11: 48 | D11: 71 | E11: 24 | F11: 83 | K11: =ABS(A11-$J$1) -> 6 | L11: =ABS(B11-$J$2) -> 14 | M11: =ABS(C11-$J$3) -> 25 | N11: =ABS(D11-$J$4) -> 48 | O11: =ABS(E11-$J$5) -> 16 | P11: =ABS(F11-$J$6) -> 45
A12: 5 | B12: 17 | C12: 36 | D12: 60 | E12: 44 | F12: 64 | K12: =ABS(A12-$J$1) -> 3 | L12: =ABS(B12-$J$2) -> 14 | M12: =ABS(C12-$J$3) -> 13 | N12: =ABS(D12-$J$4) -> 37 | O12: =ABS(E12-$J$5) -> 4 | P12: =ABS(F12-$J$6) -> 26
A13: 5 | B13: 16 | C13: 58 | D13: 82 | E13: 14 | F13: 98 | K13: =ABS(A13-$J$1) -> 3 | L13: =ABS(B13-$J$2) -> 13 | M13: =ABS(C13-$J$3) -> 35 | N13: =ABS(D13-$J$4) -> 59 | O13: =ABS(E13-$J$5) -> 26 | P13: =ABS(F13-$J$6) -> 60
A14: 2 | B14: 16 | C14: 50 | D14: 82 | E14: 31 | F14: 94 | K14: =ABS(A14-$J$1) -> 0 | L14: =ABS(B14-$J$2) -> 13 | M14: =ABS(C14-$J$3) -> 27 | N14: =ABS(D14-$J$4) -> 59 | O14: =ABS(E14-$J$5) -> 9 | P14: =ABS(F14-$J$6) -> 56
A15: 2 | B15: 16 | C15: 50 | D15: 64 | E15: 35 | F15: 81 | K15: =ABS(A15-$J$1) -> 0 | L15: =ABS(B15-$J$2) -> 13 | M15: =ABS(C15-$J$3) -> 27 | N15: =ABS(D15-$J$4) -> 41 | O15: =ABS(E15-$J$5) -> 5 | P15: =ABS(F15-$J$6) -> 43
A16: 2 | B16: 16 | C16: 41 | D16: 74 | E16: 37 | F16: 72 | K16: =ABS(A16-$J$1) -> 0 | L16: =ABS(B16-$J$2) -> 13 | M16: =ABS(C16-$J$3) -> 18 | N16: =ABS(D16-$J$4) -> 51 | O16: =ABS(E16-$J$5) -> 3 | P16: =ABS(F16-$J$6) -> 34
A17: 5 | B17: 16 | C17: 32 | D17: 67 | E17: 24 | F17: 60 | K17: =ABS(A17-$J$1) -> 3 | L17: =ABS(B17-$J$2) -> 13 | M17: =ABS(C17-$J$3) -> 9 | N17: =ABS(D17-$J$4) -> 44 | O17: =ABS(E17-$J$5) -> 16 | P17: =ABS(F17-$J$6) -> 22
A18: 2 | B18: 15 | C18: 61 | D18: 68 | E18: 27 | F18: 121 | K18: =ABS(A18-$J$1) -> 0 | L18: =ABS(B18-$J$2) -> 12 | M18: =ABS(C18-$J$3) -> 38 | N18: =ABS(D18-$J$4) -> 45 | O18: =ABS(E18-$J$5) -> 13 | P18: =ABS(F18-$J$6) -> 83
A19: 5 | B19: 15 | C19: 57 | D19: 64 | E19: 16 | F19: 106 | K19: =ABS(A19-$J$1) -> 3 | L19: =ABS(B19-$J$2) -> 12 | M19: =ABS(C19-$J$3) -> 34 | N19: =ABS(D19-$J$4) -> 41 | O19: =ABS(E19-$J$5) -> 24 | P19: =ABS(F19-$J$6) -> 68
... A1599: 52 | B1599: 6 | C1599: 50 | D1599: 51 | E1599: 49 | F1599: 76 | K1599: =ABS(A1599-$J$1) -> 50 | L1599: =ABS(B1599-$J$2) -> 3 | M1599: =ABS(C1599-$J$3) -> 27 | N1599: =ABS(D1599-$J$4) -> 28 | O1599: =ABS(E1599-$J$5) -> 9 | P1599: =ABS(F1599-$J$6) -> 38
A1600: 10 | B1600: 6 | C1600: 50 | D1600: 51 | E1600: 45 | K1600: =ABS(A1600-$J$1) -> 8 | L1600: =ABS(B1600-$J$2) -> 3 | M1600: =ABS(C1600-$J$3) -> 27 | N1600: =ABS(D1600-$J$4) -> 28 | O1600: =ABS(E1600-$J$5) -> 5 | P1600: =ABS(F1600-$J$6) -> 38
A1601: 8 | B1601: 6 | C1601: 50 | D1601: 48 | E1601: 35 | F1601: 95 | K1601: =ABS(A1601-$J$1) -> 6 | L1601: =ABS(B1601-$J$2) -> 3 | M1601: =ABS(C1601-$J$3) -> 27 | N1601: =ABS(D1601-$J$4) -> 25 | O1601: =ABS(E1601-$J$5) -> 5 | P1601: =ABS(F1601-$J$6) -> 57
A1602: 22 | B1602: 6 | C1602: 50 | D1602: 47 | E1602: 84 | F1602: 89 | K1602: =ABS(A1602-$J$1) -> 20 | L1602: =ABS(B1602-$J$2) -> 3 | M1602: =ABS(C1602-$J$3) -> 27 | N1602: =ABS(D1602-$J$4) -> 24 | O1602: =ABS(E1602-$J$5) -> 44 | P1602: =ABS(F1602-$J$6) -> 51
A1603: 8 | B1603: 6 | C1603: 50 | D1603: 45 | E1603: 42 | F1603: 78 | K1603: =ABS(A1603-$J$1) -> 6 | L1603: =ABS(B1603-$J$2) -> 3 | M1603: =ABS(C1603-$J$3) -> 27 | N1603: =ABS(D1603-$J$4) -> 22 | O1603: =ABS(E1603-$J$5) -> 2 | P1603: =ABS(F1603-$J$6) -> 40
A1604: 2 | B1604: 6 | C1604: 50 | D1604: 42 | E1604: 129 | F1604: 77 | K1604: =ABS(A1604-$J$1) -> 0 | L1604: =ABS(B1604-$J$2) -> 3 | M1604: =ABS(C1604-$J$3) -> 27 | N1604: =ABS(D1604-$J$4) -> 19 | O1604: =ABS(E1604-$J$5) -> 89 | P1604: =ABS(F1604-$J$6) -> 39
A1605: 8 | B1605: 6 | C1605: 50 | D1605: 42 | E1605: 80 | F1605: 91 | K1605: =ABS(A1605-$J$1) -> 6 | L1605: =ABS(B1605-$J$2) -> 3 | M1605: =ABS(C1605-$J$3) -> 27 | N1605: =ABS(D1605-$J$4) -> 19 | O1605: =ABS(E1605-$J$5) -> 40 | P1605: =ABS(F1605-$J$6) -> 53
A1606: 2 | B1606: 6 | C1606: 50 | D1606: 42 | E1606: 61 | F1606: 116 | K1606: =ABS(A1606-$J$1) -> 0 | L1606: =ABS(B1606-$J$2) -> 3 | M1606: =ABS(C1606-$J$3) -> 27 | N1606: =ABS(D1606-$J$4) -> 19 | O1606: =ABS(E1606-$J$5) -> 21 | P1606: =ABS(F1606-$J$6) -> 78
A1607: 5 | B1607: 6 | C1607: 50 | D1607: 40 | E1607: 40 | F1607: 81 | K1607: =ABS(A1607-$J$1) -> 3 | L1607: =ABS(B1607-$J$2) -> 3 | M1607: =ABS(C1607-$J$3) -> 27 | N1607: =ABS(D1607-$J$4) -> 17 | O1607: =ABS(E1607-$J$5) -> 0 | P1607: =ABS(F1607-$J$6) -> 43
A1608: 5 | B1608: 6 | C1608: 50 | D1608: 38 | E1608: 36 | F1608: 93 | K1608: =ABS(A1608-$J$1) -> 3 | L1608: =ABS(B1608-$J$2) -> 3 | M1608: =ABS(C1608-$J$3) -> 27 | N1608: =ABS(D1608-$J$4) -> 15 | O1608: =ABS(E1608-$J$5) -> 4 | P1608: =ABS(F1608-$J$6) -> 55
A1609: 8 | B1609: 6 | C1609: 50 | D1609: 37 | E1609: 129 | F1609: 85 | K1609: =ABS(A1609-$J$1) -> 6 | L1609: =ABS(B1609-$J$2) -> 3 | M1609: =ABS(C1609-$J$3) -> 27 | N1609: =ABS(D1609-$J$4) -> 14 | O1609: =ABS(E1609-$J$5) -> 89 | P1609: =ABS(F1609-$J$6) -> 47
A1610: 2 | B1610: 6 | C1610: 50 | D1610: 37 | E1610: 44 | F1610: 88 | K1610: =ABS(A1610-$J$1) -> 0 | L1610: =ABS(B1610-$J$2) -> 3 | M1610: =ABS(C1610-$J$3) -> 27 | N1610: =ABS(D1610-$J$4) -> 14 | O1610: =ABS(E1610-$J$5) -> 4 | P1610: =ABS(F1610-$J$6) -> 50
A1611: 8 | B1611: 6 | C1611: 50 | D1611: 35 | E1611: 126 | F1611: 82 | K1611: =ABS(A1611-$J$1) -> 6 | L1611: =ABS(B1611-$J$2) -> 3 | M1611: =ABS(C1611-$J$3) -> 27 | N1611: =ABS(D1611-$J$4) -> 12 | O1611: =ABS(E1611-$J$5) -> 86 | P1611: =ABS(F1611-$J$6) -> 44
A1612: 5 | B1612: 6 | C1612: 50 | D1612: 33 | E1612: 71 | F1612: 63 | K1612: =ABS(A1612-$J$1) -> 3 | L1612: =ABS(B1612-$J$2) -> 3 | M1612: =ABS(C1612-$J$3) -> 27 | N1612: =ABS(D1612-$J$4) -> 10 | O1612: =ABS(E1612-$J$5) -> 31 | P1612: =ABS(F1612-$J$6) -> 25
... A2634: 2 | B2634: 6 | C2634: 17 | D2634: 48 | E2634: 27 | F2634: 21 | K2634: =ABS(A2634-$J$1) -> 0 | L2634: =ABS(B2634-$J$2) -> 3 | M2634: =ABS(C2634-$J$3) -> 6 | N2634: =ABS(D2634-$J$4) -> 25 | O2634: =ABS(E2634-$J$5) -> 13 | P2634: =ABS(F2634-$J$6) -> 17
A2635: 2 | B2635: 6 | C2635: 17 | D2635: 47 | E2635: 27 | K2635: =ABS(A2635-$J$1) -> 0 | L2635: =ABS(B2635-$J$2) -> 3 | M2635: =ABS(C2635-$J$3) -> 6 | N2635: =ABS(D2635-$J$4) -> 24 | O2635: =ABS(E2635-$J$5) -> 13 | P2635: =ABS(F2635-$J$6) -> 38
A2636: 2 | B2636: 6 | C2636: 17 | D2636: 45 | E2636: 26 | F2636: 29 | K2636: =ABS(A2636-$J$1) -> 0 | L2636: =ABS(B2636-$J$2) -> 3 | M2636: =ABS(C2636-$J$3) -> 6 | N2636: =ABS(D2636-$J$4) -> 22 | O2636: =ABS(E2636-$J$5) -> 14 | P2636: =ABS(F2636-$J$6) -> 9
A2637: 5 | B2637: 6 | C2637: 17 | D2637: 45 | E2637: 25 | F2637: 34 | K2637: =ABS(A2637-$J$1) -> 3 | L2637: =ABS(B2637-$J$2) -> 3 | M2637: =ABS(C2637-$J$3) -> 6 | N2637: =ABS(D2637-$J$4) -> 22 | O2637: =ABS(E2637-$J$5) -> 15 | P2637: =ABS(F2637-$J$6) -> 4
A2638: 2 | B2638: 6 | C2638: 17 | D2638: 45 | E2638: 23 | F2638: 37 | K2638: =ABS(A2638-$J$1) -> 0 | L2638: =ABS(B2638-$J$2) -> 3 | M2638: =ABS(C2638-$J$3) -> 6 | N2638: =ABS(D2638-$J$4) -> 22 | O2638: =ABS(E2638-$J$5) -> 17 | P2638: =ABS(F2638-$J$6) -> 1
A2639: 2 | B2639: 6 | C2639: 17 | D2639: 43 | E2639: 30 | F2639: 37 | K2639: =ABS(A2639-$J$1) -> 0 | L2639: =ABS(B2639-$J$2) -> 3 | M2639: =ABS(C2639-$J$3) -> 6 | N2639: =ABS(D2639-$J$4) -> 20 | O2639: =ABS(E2639-$J$5) -> 10 | P2639: =ABS(F2639-$J$6) -> 1
A2640: 2 | B2640: 6 | C2640: 17 | D2640: 40 | E2640: 29 | F2640: 24 | K2640: =ABS(A2640-$J$1) -> 0 | L2640: =ABS(B2640-$J$2) -> 3 | M2640: =ABS(C2640-$J$3) -> 6 | N2640: =ABS(D2640-$J$4) -> 17 | O2640: =ABS(E2640-$J$5) -> 11 | P2640: =ABS(F2640-$J$6) -> 14
...

Sheet 工作表2
A1: 95 | B1: 23 | C1: 113 | D1: 101 | E1: 202 | F1: 169 | I1: =MAX(L:L) -> 10181 | K1: SO2 | M1: FNDI | N1: p | O1: Bayesian | Q1: robust Z | R1: =MAX(T:T) -> 6745 | S1: CO | U1: FNDI | V1: p | W1: Bayesian | Y1: robust Z
A2: 86 | B2: 22 | C2: 109 | D2: 82 | E2: 187 | F2: 165 | I2: =MIN(L:L) -> 1 | K2: 95 | L2: =COUNTIFS(工作表1!A:A,"=" & K2) -> 1 | M2: =ABS(K2-$I$13)/$I$16 -> 1.1663043 | N2: =COUNTIFS($L$2:$L$47,"<="&L2)/46 -> 0.26086957 | O2: =L2/$L$48 -> 9.8222179e-05 | P2: =ABS(K2-$I$11) -> 42.5 | Q2: =0.6745*(K2-$I$11)/$I$12 -> 1.4333125 | R2: =MIN(T:T) -> 1 | S2: 23 | T2: =COUNTIFS(工作表1!B:B,"=" & S2) -> 1 | U2: =ABS(S2-$R$14)/$R$16 -> 1.147619 | V2: =COUNTIFS($T$2:$T$21,"<="&T2)/20 -> 0.15 | W2: =T2/$T$22 -> 0.00014825797 | X2: =ABS(S2-$R$11) -> 12.5 | Y2: =0.6745*(S2-$R$11)/$R$12 -> 1.5329545
A3: 85 | B3: 20 | C3: 108 | D3: 79 | E3: 185 | F3: 156 | I3: =MAX(N:N) -> 1 | K3: 86 | L3: =COUNTIFS(工作表1!A:A,"=" & K3) -> 1 | M3: =ABS(K3-$I$13)/$I$16 -> 0.94130435 | N3: =COUNTIFS($L$2:$L$47,"<="&L3)/46 -> 0.26086957 | O3: =L3/$L$48 -> 9.8222179e-05 | P3: =ABS(K3-$I$11) -> 33.5 | Q3: =0.6745*(K3-$I$11)/$I$12 -> 1.1297875 | R3: =MAX(V:V) -> 1 | S3: 22 | T3: =COUNTIFS(工作表1!B:B,"=" & S3) -> 1 | U3: =ABS(S3-$R$14)/$R$16 -> 1.052381 | V3: =COUNTIFS($T$2:$T$21,"<="&T3)/20 -> 0.15 | W3: =T3/$T$22 -> 0.00014825797 | X3: =ABS(S3-$R$11) -> 11.5 | Y3: =0.6745*(S3-$R$11)/$R$12 -> 1.4103182
A4: 83 | B4: 18 | C4: 107 | D4: 78 | E4: 182 | F4: 155 | I4: =MIN(N:N) -> 0.26086957 | K4: 85 | L4: =COUNTIFS(工作表1!A:A,"=" & K4) -> 1 | M4: =ABS(K4-$I$13)/$I$16 -> 0.91630435 | N4: =COUNTIFS($L$2:$L$47,"<="&L4)/46 -> 0.26086957 | O4: =L4/$L$48 -> 9.8222179e-05 | P4: =ABS(K4-$I$11) -> 32.5 | Q4: =0.6745*(K4-$I$11)/$I$12 -> 1.0960625 | R4: =MIN(V:V) -> 0.15 | S4: 20 | T4: =COUNTIFS(工作表1!B:B,"=" & S4) -> 1 | U4: =ABS(S4-$R$14)/$R$16 -> 0.86190476 | V4: =COUNTIFS($T$2:$T$21,"<="&T4)/20 -> 0.15 | W4: =T4/$T$22 -> 0.00014825797 | X4: =ABS(S4-$R$11) -> 9.5 | Y4: =0.6745*(S4-$R$11)/$R$12 -> 1.1650455
A5: 81 | B5: 17 | C5: 106 | D5: 77 | E5: 177 | F5: 154 | I5: =MAX(O:O) -> 1 | K5: 83 | L5: =COUNTIFS(工作表1!A:A,"=" & K5) -> 1 | M5: =ABS(K5-$I$13)/$I$16 -> 0.86630435 | N5: =COUNTIFS($L$2:$L$47,"<="&L5)/46 -> 0.26086957 | O5: =L5/$L$48 -> 9.8222179e-05 | P5: =ABS(K5-$I$11) -> 30.5 | Q5: =0.6745*(K5-$I$11)/$I$12 -> 1.0286125 | R5: =MAX(W:W) -> 1 | S5: 18 | T5: =COUNTIFS(工作表1!B:B,"=" & S5) -> 4 | U5: =ABS(S5-$R$14)/$R$16 -> 0.67142857 | V5: =COUNTIFS($T$2:$T$21,"<="&T5)/20 -> 0.25 | W5: =T5/$T$22 -> 0.00059303188 | X5: =ABS(S5-$R$11) -> 7.5 | Y5: =0.6745*(S5-$R$11)/$R$12 -> 0.91977273
A6: 79 | B6: 16 | C6: 105 | D6: 76 | E6: 174 | F6: 152 | I6: =MIN(O:O) -> 9.8222179e-05 | K6: 81 | L6: =COUNTIFS(工作表1!A:A,"=" & K6) -> 1 | M6: =ABS(K6-$I$13)/$I$16 -> 0.81630435 | N6: =COUNTIFS($L$2:$L$47,"<="&L6)/46 -> 0.26086957 | O6: =L6/$L$48 -> 9.8222179e-05 | P6: =ABS(K6-$I$11) -> 28.5 | Q6: =0.6745*(K6-$I$11)/$I$12 -> 0.9611625 | R6: =MIN(W:W) -> 0.00014825797 | S6: 17 | T6: =COUNTIFS(工作表1!B:B,"=" & S6) -> 4 | U6: =ABS(S6-$R$14)/$R$16 -> 0.57619048 | V6: =COUNTIFS($T$2:$T$21,"<="&T6)/20 -> 0.25 | W6: =T6/$T$22 -> 0.00059303188 | X6: =ABS(S6-$R$11) -> 6.5 | Y6: =0.6745*(S6-$R$11)/$R$12 -> 0.79713636
A7: 78 | B7: 15 | C7: 104 | D7: 75 | E7: 169 | F7: 151 | I7: =MAX(Q:Q) -> 1.4333125 | K7: 79 | L7: =COUNTIFS(工作表1!A:A,"=" & K7) -> 2 | M7: =ABS(K7-$I$13)/$I$16 -> 0.76630435 | N7: =COUNTIFS($L$2:$L$47,"<="&L7)/46 -> 0.45652174 | O7: =L7/$L$48 -> 0.00019644436 | P7: =ABS(K7-$I$11) -> 26.5 | Q7: =0.6745*(K7-$I$11)/$I$12 -> 0.8937125 | R7: =MAX(Y:Y) -> 1.5329545 | S7: 16 | T7: =COUNTIFS(工作表1!B:B,"=" & S7) -> 5 | U7: =ABS(S7-$R$14)/$R$16 -> 0.48095238 | V7: =COUNTIFS($T$2:$T$21,"<="&T7)/20 -> 0.3 | W7: =T7/$T$22 -> 0.00074128984 | X7: =ABS(S7-$R$11) -> 5.5 | Y7: =0.6745*(S7-$R$11)/$R$12 -> 0.6745
A8: 76 | B8: 14 | C8: 103 | D8: 74 | E8: 166 | F8: 150 | I8: =MIN(Q:Q) -> -1.7705625 | K8: 78 | L8: =COUNTIFS(工作表1!A:A,"=" & K8) -> 1 | M8: =ABS(K8-$I$13)/$I$16 -> 0.74130435 | N8: =COUNTIFS($L$2:$L$47,"<="&L8)/46 -> 0.26086957 | O8: =L8/$L$48 -> 9.8222179e-05 | P8: =ABS(K8-$I$11) -> 25.5 | Q8: =0.6745*(K8-$I$11)/$I$12 -> 0.8599875 | R8: =MIN(Y:Y) -> -1.2876818 | S8: 15 | T8: =COUNTIFS(工作表1!B:B,"=" & S8) -> 10 | U8: =ABS(S8-$R$14)/$R$16 -> 0.38571429 | V8: =COUNTIFS($T$2:$T$21,"<="&T8)/20 -> 0.35 | W8: =T8/$T$22 -> 0.0014825797 | X8: =ABS(S8-$R$11) -> 4.5 | Y8: =0.6745*(S8-$R$11)/$R$12 -> 0.55186364
A9: 73 | B9: 12 | C9: 102 | D9: 73 | E9: 164 | F9: 149 | I9: =MAX(L2:L47) -> 10181 | K9: 76 | L9: =COUNTIFS(工作表1!A:A,"=" & K9) -> 2 | M9: =ABS(K9-$I$13)/$I$16 -> 0.69130435 | N9: =COUNTIFS($L$2:$L$47,"<="&L9)/46 -> 0.45652174 | O9: =L9/$L$48 -> 0.00019644436 | P9: =ABS(K9-$I$11) -> 23.5 | Q9: =0.6745*(K9-$I$11)/$I$12 -> 0.7925375 | R9: =MAX(T2:T21) -> 6745 | S9: 14 | T9: =COUNTIFS(工作表1!B:B,"=" & S9) -> 16 | U9: =ABS(S9-$R$14)/$R$16 -> 0.29047619 | V9: =COUNTIFS($T$2:$T$21,"<="&T9)/20 -> 0.5 | W9: =T9/$T$22 -> 0.0023721275 | X9: =ABS(S9-$R$11) -> 3.5 | Y9: =0.6745*(S9-$R$11)/$R$12 -> 0.42922727
A10: 72 | B10: 11 | C10: 101 | D10: 72 | E10: 161 | F10: 148 | K10: 73 | L10: =COUNTIFS(工作表1!A:A,"=" & K10) -> 1 | M10: =ABS(K10-$I$13)/$I$16 -> 0.61630435 | N10: =COUNTIFS($L$2:$L$47,"<="&L10)/46 -> 0.26086957 | O10: =L10/$L$48 -> 9.8222179e-05 | P10: =ABS(K10-$I$11) -> 20.5 | Q10: =0.6745*(K10-$I$11)/$I$12 -> 0.6913625 | S10: 12 | T10: =COUNTIFS(工作表1!B:B,"=" & S10) -> 13 | U10: =ABS(S10-$R$14)/$R$16 -> 0.1 | V10: =COUNTIFS($T$2:$T$21,"<="&T10)/20 -> 0.4 | W10: =T10/$T$22 -> 0.0019273536 | X10: =ABS(S10-$R$11) -> 1.5 | Y10: =0.6745*(S10-$R$11)/$R$12 -> 0.18395455
A11: 71 | B11: 10 | C11: 100 | D11: 71 | E11: 159 | F11: 147 | I11: =MEDIAN(K2:K47) -> 52.5 | K11: 72 | L11: =COUNTIFS(工作表1!A:A,"=" & K11) -> 2 | M11: =ABS(K11-$I$13)/$I$16 -> 0.59130435 | N11: =COUNTIFS($L$2:$L$47,"<="&L11)/46 -> 0.45652174 | O11: =L11/$L$48 -> 0.00019644436 | P11: =ABS(K11-$I$11) -> 19.5 | Q11: =0.6745*(K11-$I$11)/$I$12 -> 0.6576375 | R11: =MEDIAN(S2:S21) -> 10.5 | S11: 11 | T11: =COUNTIFS(工作表1!B:B,"=" & S11) -> 15 | U11: =ABS(S11-$R$14)/$R$16 -> 0.0047619048 | V11: =COUNTIFS($T$2:$T$21,"<="&T11)/20 -> 0.45 | W11: =T11/$T$22 -> 0.0022238695 | X11: =ABS(S11-$R$11) -> 0.5 | Y11: =0.6745*(S11-$R$11)/$R$12 -> 0.061318182
A12: 69 | B12: 9 | C12: 99 | D12: 70 | E12: 156 | F12: 146 | I12: =MEDIAN(P2:P47) -> 20 | K12: 71 | L12: =COUNTIFS(工作表1!A:A,"=" & K12) -> 1 | M12: =ABS(K12-$I$13)/$I$16 -> 0.56630435 | N12: =COUNTIFS($L$2:$L$47,"<="&L12)/46 -> 0.26086957 | O12: =L12/$L$48 -> 9.8222179e-05 | P12: =ABS(K12-$I$11) -> 18.5 | Q12: =0.6745*(K12-$I$11)/$I$12 -> 0.6239125 | R12: =MEDIAN(X2:X21) -> 5.5 | S12: 10 | T12: =COUNTIFS(工作表1!B:B,"=" & S12) -> 42 | U12: =ABS(S12-$R$14)/$R$16 -> 0.09047619 | V12: =COUNTIFS($T$2:$T$21,"<="&T12)/20 -> 0.55 | W12: =T12/$T$22 -> 0.0062268347 | X12: =ABS(S12-$R$11) -> 0.5 | Y12: =0.6745*(S12-$R$11)/$R$12 -> -0.061318182
A13: 67 | B13: 8 | C13: 97 | D13: 69 | E13: 154 | F13: 145 | I13: =AVERAGE(K2:K47) -> 48.347826 | K13: 69 | L13: =COUNTIFS(工作表1!A:A,"=" & K13) -> 1 | M13: =ABS(K13-$I$13)/$I$16 -> 0.51630435 | N13: =COUNTIFS($L$2:$L$47,"<="&L13)/46 -> 0.26086957 | O13: =L13/$L$48 -> 9.8222179e-05 | P13: =ABS(K13-$I$11) -> 16.5 | Q13: =0.6745*(K13-$I$11)/$I$12 -> 0.5564625 | S13: 9 | T13: =COUNTIFS(工作表1!B:B,"=" & S13) -> 112 | U13: =ABS(S13-$R$14)/$R$16 -> 0.18571429 | V13: =COUNTIFS($T$2:$T$21,"<="&T13)/20 -> 0.6 | W13: =T13/$T$22 -> 0.016604893 | X13: =ABS(S13-$R$11) -> 1.5 | Y13: =0.6745*(S13-$R$11)/$R$12 -> -0.18395455
A14: 64 | B14: 7 | C14: 96 | D14: 68 | E14: 151 | F14: 144 | I14: =_xlfn.STDEV.P(K2:K47) -> 25.376485 | K14: 67 | L14: =COUNTIFS(工作表1!A:A,"=" & K14) -> 1 | M14: =ABS(K14-$I$13)/$I$16 -> 0.46630435 | N14: =COUNTIFS($L$2:$L$47,"<="&L14)/46 -> 0.26086957 | O14: =L14/$L$48 -> 9.8222179e-05 | P14: =ABS(K14-$I$11) -> 14.5 | Q14: =0.6745*(K14-$I$11)/$I$12 -> 0.4890125 | R14: =AVERAGE(S2:S21) -> 10.95 | S14: 8 | T14: =COUNTIFS(工作表1!B:B,"=" & S14) -> 203 | U14: =ABS(S14-$R$14)/$R$16 -> 0.28095238 | V14: =COUNTIFS($T$2:$T$21,"<="&T14)/20 -> 0.65 | W14: =T14/$T$22 -> 0.030096368 | X14: =ABS(S14-$R$11) -> 2.5 | Y14: =0.6745*(S14-$R$11)/$R$12 -> -0.30659091
A15: 62 | B15: 6 | C15: 95 | D15: 67 | E15: 150 | F15: 143 | K15: 64 | L15: =COUNTIFS(工作表1!A:A,"=" & K15) -> 2 | M15: =ABS(K15-$I$13)/$I$16 -> 0.39130435 | N15: =COUNTIFS($L$2:$L$47,"<="&L15)/46 -> 0.45652174 | O15: =L15/$L$48 -> 0.00019644436 | P15: =ABS(K15-$I$11) -> 11.5 | Q15: =0.6745*(K15-$I$11)/$I$12 -> 0.3878375 | R15: =_xlfn.STDEV.P(S2:S21) -> 6.8518246 | S15: 7 | T15: =COUNTIFS(工作表1!B:B,"=" & S15) -> 621 | U15: =ABS(S15-$R$14)/$R$16 -> 0.37619048 | V15: =COUNTIFS($T$2:$T$21,"<="&T15)/20 -> 0.75 | W15: =T15/$T$22 -> 0.092068199 | X15: =ABS(S15-$R$11) -> 3.5 | Y15: =0.6745*(S15-$R$11)/$R$12 -> -0.42922727
A16: 61 | B16: 5 | C16: 94 | D16: 66 | E16: 146 | F16: 141 | I16: =QUARTILE(K2:K47,3)-QUARTILE(K2:K47,1) -> 40 | K16: 62 | L16: =COUNTIFS(工作表1!A:A,"=" & K16) -> 1 | M16: =ABS(K16-$I$13)/$I$16 -> 0.34130435 | N16: =COUNTIFS($L$2:$L$47,"<="&L16)/46 -> 0.26086957 | O16: =L16/$L$48 -> 9.8222179e-05 | P16: =ABS(K16-$I$11) -> 9.5 | Q16: =0.6745*(K16-$I$11)/$I$12 -> 0.3203875 | R16: =QUARTILE(S2:S21,3)-QUARTILE(S2:S21,1) -> 10.5 | S16: 6 | T16: =COUNTIFS(工作表1!B:B,"=" & S16) -> 1755 | U16: =ABS(S16-$R$14)/$R$16 -> 0.47142857 | V16: =COUNTIFS($T$2:$T$21,"<="&T16)/20 -> 0.8 | W16: =T16/$T$22 -> 0.26019274 | X16: =ABS(S16-$R$11) -> 4.5 | Y16: =0.6745*(S16-$R$11)/$R$12 -> -0.55186364
A17: 60 | B17: 3 | C17: 93 | D17: 65 | E17: 143 | F17: 140 | K17: 61 | L17: =COUNTIFS(工作表1!A:A,"=" & K17) -> 2 | M17: =ABS(K17-$I$13)/$I$16 -> 0.31630435 | N17: =COUNTIFS($L$2:$L$47,"<="&L17)/46 -> 0.45652174 | O17: =L17/$L$48 -> 0.00019644436 | P17: =ABS(K17-$I$11) -> 8.5 | Q17: =0.6745*(K17-$I$11)/$I$12 -> 0.2866625 | S17: 5 | T17: =COUNTIFS(工作表1!B:B,"=" & S17) -> 3942 | U17: =ABS(S17-$R$14)/$R$16 -> 0.56666667 | V17: =COUNTIFS($T$2:$T$21,"<="&T17)/20 -> 0.85 | W17: =T17/$T$22 -> 0.58443291 | X17: =ABS(S17-$R$11) -> 5.5 | Y17: =0.6745*(S17-$R$11)/$R$12 -> -0.6745
A18: 59 | B18: 2 | C18: 92 | D18: 64 | E18: 140 | F18: 139 | K18: 60 | L18: =COUNTIFS(工作表1!A:A,"=" & K18) -> 1 | M18: =ABS(K18-$I$13)/$I$16 -> 0.29130435 | N18: =COUNTIFS($L$2:$L$47,"<="&L18)/46 -> 0.26086957 | O18: =L18/$L$48 -> 9.8222179e-05 | P18: =ABS(K18-$I$11) -> 7.5 | Q18: =0.6745*(K18-$I$11)/$I$12 -> 0.2529375 | S18: 3 | T18: =COUNTIFS(工作表1!B:B,"=" & S18) -> 6165 | U18: =ABS(S18-$R$14)/$R$16 -> 0.75714286 | V18: =COUNTIFS($T$2:$T$21,"<="&T18)/20 -> 0.95 | W18: =T18/$T$22 -> 0.91401038 | X18: =ABS(S18-$R$11) -> 7.5 | Y18: =0.6745*(S18-$R$11)/$R$12 -> -0.91977273
A19: 57 | B19: 1 | C19: 91 | D19: 63 | E19: 136 | F19: 138 | K19: 59 | L19: =COUNTIFS(工作表1!A:A,"=" & K19) -> 2 | M19: =ABS(K19-$I$13)/$I$16 -> 0.26630435 | N19: =COUNTIFS($L$2:$L$47,"<="&L19)/46 -> 0.45652174 | O19: =L19/$L$48 -> 0.00019644436 | P19: =ABS(K19-$I$11) -> 6.5 | Q19: =0.6745*(K19-$I$11)/$I$12 -> 0.2192125 | S19: 2 | T19: =COUNTIFS(工作表1!B:B,"=" & S19) -> 6745 | U19: =ABS(S19-$R$14)/$R$16 -> 0.85238095 | V19: =COUNTIFS($T$2:$T$21,"<="&T19)/20 -> 1 | W19: =T19/$T$22 -> 1 | X19: =ABS(S19-$R$11) -> 8.5 | Y19: =0.6745*(S19-$R$11)/$R$12 -> -1.0424091
A20: 56 | B20: 0 | C20: 90 | D20: 62 | E20: 132 | F20: 137 | K20: 57 | L20: =COUNTIFS(工作表1!A:A,"=" & K20) -> 2 | M20: =ABS(K20-$I$13)/$I$16 -> 0.21630435 | N20: =COUNTIFS($L$2:$L$47,"<="&L20)/46 -> 0.45652174 | O20: =L20/$L$48 -> 0.00019644436 | P20: =ABS(K20-$I$11) -> 4.5 | Q20: =0.6745*(K20-$I$11)/$I$12 -> 0.1517625 | S20: 1 | T20: =COUNTIFS(工作表1!B:B,"=" & S20) -> 4108 | U20: =ABS(S20-$R$14)/$R$16 -> 0.94761905 | V20: =COUNTIFS($T$2:$T$21,"<="&T20)/20 -> 0.9 | W20: =T20/$T$22 -> 0.60904374 | X20: =ABS(S20-$R$11) -> 9.5 | Y20: =0.6745*(S20-$R$11)/$R$12 -> -1.1650455
A21: 55 | C21: 89 | D21: 61 | E21: 129 | F21: 136 | K21: 56 | L21: =COUNTIFS(工作表1!A:A,"=" & K21) -> 4 | M21: =ABS(K21-$I$13)/$I$16 -> 0.19130435 | N21: =COUNTIFS($L$2:$L$47,"<="&L21)/46 -> 0.5 | O21: =L21/$L$48 -> 0.00039288871 | P21: =ABS(K21-$I$11) -> 3.5 | Q21: =0.6745*(K21-$I$11)/$I$12 -> 0.1180375 | S21: 0 | T21: =COUNTIFS(工作表1!B:B,"=" & S21) -> 331 | U21: =ABS(S21-$R$14)/$R$16 -> 1.0428571 | V21: =COUNTIFS($T$2:$T$21,"<="&T21)/20 -> 0.7 | W21: =T21/$T$22 -> 0.049073388 | X21: =ABS(S21-$R$11) -> 10.5 | Y21: =0.6745*(S21-$R$11)/$R$12 -> -1.2876818
A22: 54 | C22: 88 | D22: 60 | E22: 126 | F22: 135 | K22: 55 | L22: =COUNTIFS(工作表1!A:A,"=" & K22) -> 2 | M22: =ABS(K22-$I$13)/$I$16 -> 0.16630435 | N22: =COUNTIFS($L$2:$L$47,"<="&L22)/46 -> 0.45652174 | O22: =L22/$L$48 -> 0.00019644436 | P22: =ABS(K22-$I$11) -> 2.5 | Q22: =0.6745*(K22-$I$11)/$I$12 -> 0.0843125 | T22: =MAX(T2:T21) -> 6745
A23: 53 | C23: 87 | D23: 59 | E23: 122 | F23: 134 | K23: 54 | L23: =COUNTIFS(工作表1!A:A,"=" & K23) -> 4 | M23: =ABS(K23-$I$13)/$I$16 -> 0.14130435 | N23: =COUNTIFS($L$2:$L$47,"<="&L23)/46 -> 0.5 | O23: =L23/$L$48 -> 0.00039288871 | P23: =ABS(K23-$I$11) -> 1.5 | Q23: =0.6745*(K23-$I$11)/$I$12 -> 0.0505875
A24: 52 | C24: 86 | D24: 58 | E24: 118 | F24: 133 | K24: 53 | L24: =COUNTIFS(工作表1!A:A,"=" & K24) -> 6 | M24: =ABS(K24-$I$13)/$I$16 -> 0.11630435 | N24: =COUNTIFS($L$2:$L$47,"<="&L24)/46 -> 0.56521739 | O24: =L24/$L$48 -> 0.00058933307 | P24: =ABS(K24-$I$11) -> 0.5 | Q24: =0.6745*(K24-$I$11)/$I$12 -> 0.0168625
A25: 51 | C25: 85 | D25: 57 | E25: 115 | F25: 132 | K25: 52 | L25: =COUNTIFS(工作表1!A:A,"=" & K25) -> 8 | M25: =ABS(K25-$I$13)/$I$16 -> 0.091304348 | N25: =COUNTIFS($L$2:$L$47,"<="&L25)/46 -> 0.63043478 | O25: =L25/$L$48 -> 0.00078577743 | P25: =ABS(K25-$I$11) -> 0.5 | Q25: =0.6745*(K25-$I$11)/$I$12 -> -0.0168625
A26: 50 | C26: 84 | D26: 56 | E26: 112 | F26: 131 | K26: 51 | L26: =COUNTIFS(工作表1!A:A,"=" & K26) -> 2 | M26: =ABS(K26-$I$13)/$I$16 -> 0.066304348 | N26: =COUNTIFS($L$2:$L$47,"<="&L26)/46 -> 0.45652174 | O26: =L26/$L$48 -> 0.00019644436 | P26: =ABS(K26-$I$11) -> 1.5 | Q26: =0.6745*(K26-$I$11)/$I$12 -> -0.0505875
A27: 48 | C27: 83 | D27: 55 | E27: 108 | F27: 130 | K27: 50 | L27: =COUNTIFS(工作表1!A:A,"=" & K27) -> 6 | M27: =ABS(K27-$I$13)/$I$16 -> 0.041304348 | N27: =COUNTIFS($L$2:$L$47,"<="&L27)/46 -> 0.56521739 | O27: =L27/$L$48 -> 0.00058933307 | P27: =ABS(K27-$I$11) -> 2.5 | Q27: =0.6745*(K27-$I$11)/$I$12 -> -0.0843125
A28: 45 | C28: 82 | D28: 54 | E28: 104 | F28: 129 | K28: 48 | L28: =COUNTIFS(工作表1!A:A,"=" & K28) -> 5 | M28: =ABS(K28-$I$13)/$I$16 -> 0.0086956522 | N28: =COUNTIFS($L$2:$L$47,"<="&L28)/46 -> 0.52173913 | O28: =L28/$L$48 -> 0.00049111089 | P28: =ABS(K28-$I$11) -> 4.5 | Q28: =0.6745*(K28-$I$11)/$I$12 -> -0.1517625
A29: 42 | C29: 81 | D29: 53 | E29: 101 | F29: 128 | K29: 45 | L29: =COUNTIFS(工作表1!A:A,"=" & K29) -> 7 | M29: =ABS(K29-$I$13)/$I$16 -> 0.083695652 | N29: =COUNTIFS($L$2:$L$47,"<="&L29)/46 -> 0.58695652 | O29: =L29/$L$48 -> 0.00068755525 | P29: =ABS(K29-$I$11) -> 7.5 | Q29: =0.6745*(K29-$I$11)/$I$12 -> -0.2529375
A30: 40 | C30: 80 | D30: 52 | E30: 100 | F30: 127 | K30: 42 | L30: =COUNTIFS(工作表1!A:A,"=" & K30) -> 8 | M30: =ABS(K30-$I$13)/$I$16 -> 0.15869565 | N30: =COUNTIFS($L$2:$L$47,"<="&L30)/46 -> 0.63043478 | O30: =L30/$L$48 -> 0.00078577743 | P30: =ABS(K30-$I$11) -> 10.5 | Q30: =0.6745*(K30-$I$11)/$I$12 -> -0.3541125
A31: 38 | C31: 79 | D31: 51 | E31: 97 | F31: 126 | K31: 40 | L31: =COUNTIFS(工作表1!A:A,"=" & K31) -> 19 | M31: =ABS(K31-$I$13)/$I$16 -> 0.20869565 | N31: =COUNTIFS($L$2:$L$47,"<="&L31)/46 -> 0.69565217 | O31: =L31/$L$48 -> 0.0018662214 | P31: =ABS(K31-$I$11) -> 12.5 | Q31: =0.6745*(K31-$I$11)/$I$12 -> -0.4215625
A32: 35 | C32: 78 | D32: 50 | E32: 93 | F32: 125 | K32: 38 | L32: =COUNTIFS(工作表1!A:A,"=" & K32) -> 17 | M32: =ABS(K32-$I$13)/$I$16 -> 0.25869565 | N32: =COUNTIFS($L$2:$L$47,"<="&L32)/46 -> 0.65217391 | O32: =L32/$L$48 -> 0.001669777 | P32: =ABS(K32-$I$11) -> 14.5 | Q32: =0.6745*(K32-$I$11)/$I$12 -> -0.4890125
A33: 32 | C33: 77 | D33: 48 | E33: 90 | F33: 124 | K33: 35 | L33: =COUNTIFS(工作表1!A:A,"=" & K33) -> 19 | M33: =ABS(K33-$I$13)/$I$16 -> 0.33369565 | N33: =COUNTIFS($L$2:$L$47,"<="&L33)/46 -> 0.69565217 | O33: =L33/$L$48 -> 0.0018662214 | P33: =ABS(K33-$I$11) -> 17.5 | Q33: =0.6745*(K33-$I$11)/$I$12 -> -0.5901875
A34: 30 | C34: 76 | D34: 47 | E34: 87 | F34: 123 | K34: 32 | L34: =COUNTIFS(工作表1!A:A,"=" & K34) -> 29 | M34: =ABS(K34-$I$13)/$I$16 -> 0.40869565 | N34: =COUNTIFS($L$2:$L$47,"<="&L34)/46 -> 0.7173913 | O34: =L34/$L$48 -> 0.0028484432 | P34: =ABS(K34-$I$11) -> 20.5 | Q34: =0.6745*(K34-$I$11)/$I$12 -> -0.6913625
... A46: 0 | C46: 64 | D46: 27 | E46: 50 | F46: 111 | K46: 2 | L46: =COUNTIFS(工作表1!A:A,"=" & K46) -> 10181 | M46: =ABS(K46-$I$13)/$I$16 -> 1.1586957 | N46: =COUNTIFS($L$2:$L$47,"<="&L46)/46 -> 1 | O46: =L46/$L$48 -> 1 | P46: =ABS(K46-$I$11) -> 50.5 | Q46: =0.6745*(K46-$I$11)/$I$12 -> -1.7031125
C47: 63 | D47: 25 | E47: 49 | F47: 110 | K47: 0 | L47: =COUNTIFS(工作表1!A:A,"=" & K47) -> 2474 | M47: =ABS(K47-$I$13)/$I$16 -> 1.2086957 | N47: =COUNTIFS($L$2:$L$47,"<="&L47)/46 -> 0.93478261 | O47: =L47/$L$48 -> 0.24300167 | P47: =ABS(K47-$I$11) -> 52.5 | Q47: =0.6745*(K47-$I$11)/$I$12 -> -1.7705625
C48: 62 | D48: 23 | E48: 48 | F48: 109 | L48: =MAX(L2:L47) -> 10181
C49: 61 | D49: 22 | E49: 47 | F49: 108
C50: 60 | D50: 20 | E50: 46 | F50: 107
C51: 59 | D51: 18 | E51: 45 | F51: 106
...

Sheet 工作表3
C1: FNDI | D1: p | E1: Bayesian | G1: robust Z | H1: =MAX(B:B) -> 854 | K1: p | N1: Bayesian | O1: robust Z | P1: =MAX(K:K) -> 0.048642816 | S1: p | U1: Bayesian | V1: robust Z | W1: =MAX(S:S) -> 0.048518303 | Z1: fndi | AA1: p | AB1: Bayesian | AD1: modified Z | AE1: =MAX(Y:Y) -> 555
A2: 113 | B2: =COUNTIFS(工作表1!C:C,"=" & A2) -> 1 | C2: =ABS(A2-$H$14)/$H$17 -> 1.0708924 | D2: =COUNTIFS($B$2:$B$111,"<="&B2)/110 -> 0.090909091 | E2: =B2/$B$112 -> 0.0011709602 | F2: =ABS(A2-$H$11) -> 58.5 | G2: =0.6745*(A2-$H$11)/$H$12 -> 1.4348455 | H2: =MIN(B:B) -> 1 | J2: 101 | K2: =COUNTIFS(工作表1!D:D,"=" & J2)/24094 -> 4.1504109e-05 | M2: =COUNTIFS($K$2:$K$63,">="&K2)/62 -> 1 | N2: =K2/$K$64 -> 0.00085324232 | O2: =0.6745*(J2-23)/10 -> 5.2611 | P2: =MIN(K:K) -> 4.1504109e-05 | R2: 202 | S2: =COUNTIFS(工作表1!E:E,"=" & R2)/24094 -> 4.1504109e-05 | T2: =COUNTIFS($S$2:$S$93,">="&S2)/92 -> 1 | U2: =S2/$S$94 -> 0.00085543199 | V2: =0.6745*(R2-40)/9 -> 12.141 | W2: =MIN(S:S) -> 4.1504109e-05 | X2: 169 | Y2: =COUNTIFS(工作表1!F:F,"=" & X2) -> 1 | Z2: =ABS(X2-$AE$15)/$AE$18 -> 1.163482 | AA2: =COUNTIFS($Y$2:$Y$158,"<="&Y2)/157 -> 0.044585987 | AB2: =Y2/$Y$159 -> 0.0018018018 | AC2: =ABS(X2-$AE$12) -> 91 | AD2: =0.6745*(X2-$AE$12)/$AE$13 -> 1.5738333 | AE2: =MIN(Y:Y) -> 1
A3: 109 | B3: =COUNTIFS(工作表1!C:C,"=" & A3) -> 2 | C3: =ABS(A3-$H$14)/$H$17 -> 0.99749791 | D3: =COUNTIFS($B$2:$B$111,"<="&B3)/110 -> 0.13636364 | E3: =B3/$B$112 -> 0.0023419204 | F3: =ABS(A3-$H$11) -> 54.5 | G3: =0.6745*(A3-$H$11)/$H$12 -> 1.3367364 | H3: =MAX(D:D) -> 1 | J3: 82 | K3: =COUNTIFS(工作表1!D:D,"=" & J3)/24094 -> 0.00016601644 | M3: =COUNTIFS($K$2:$K$63,">="&K3)/62 -> 0.88709677 | N3: =K3/$K$64 -> 0.0034129693 | O3: =0.6745*(J3-23)/10 -> 3.97955 | P3: =MAX(M:M) -> 1 | R3: 187 | S3: =COUNTIFS(工作表1!E:E,"=" & R3)/24094 -> 4.1504109e-05 | T3: =COUNTIFS($S$2:$S$93,">="&S3)/92 -> 1 | U3: =S3/$S$94 -> 0.00085543199 | V3: =0.6745*(R3-40)/9 -> 11.016833 | W3: =MAX(T:T) -> 1 | X3: 165 | Y3: =COUNTIFS(工作表1!F:F,"=" & X3) -> 1 | Z3: =ABS(X3-$AE$15)/$AE$18 -> 1.1121999 | AA3: =COUNTIFS($Y$2:$Y$158,"<="&Y3)/157 -> 0.044585987 | AB3: =Y3/$Y$159 -> 0.0018018018 | AC3: =ABS(X3-$AE$12) -> 87 | AD3: =0.6745*(X3-$AE$12)/$AE$13 -> 1.5046538 | AE3: =MAX(AA:AA) -> 1
A4: 108 | B4: =COUNTIFS(工作表1!C:C,"=" & A4) -> 1 | C4: =ABS(A4-$H$14)/$H$17 -> 0.97914929 | D4: =COUNTIFS($B$2:$B$111,"<="&B4)/110 -> 0.090909091 | E4: =B4/$B$112 -> 0.0011709602 | F4: =ABS(A4-$H$11) -> 53.5 | G4: =0.6745*(A4-$H$11)/$H$12 -> 1.3122091 | H4: =MIN(D:D) -> 0.090909091 | J4: 79 | K4: =COUNTIFS(工作表1!D:D,"=" & J4)/24094 -> 0.00012451233 | M4: =COUNTIFS($K$2:$K$63,">="&K4)/62 -> 0.91935484 | N4: =K4/$K$64 -> 0.002559727 | O4: =0.6745*(J4-23)/10 -> 3.7772 | P4: =MIN(M:M) -> 0.016129032 | R4: 185 | S4: =COUNTIFS(工作表1!E:E,"=" & R4)/24094 -> 4.1504109e-05 | T4: =COUNTIFS($S$2:$S$93,">="&S4)/92 -> 1 | U4: =S4/$S$94 -> 0.00085543199 | V4: =0.6745*(R4-40)/9 -> 10.866944 | W4: =MIN(T:T) -> 0.010869565 | X4: 156 | Y4: =COUNTIFS(工作表1!F:F,"=" & X4) -> 2 | Z4: =ABS(X4-$AE$15)/$AE$18 -> 0.99681529 | AA4: =COUNTIFS($Y$2:$Y$158,"<="&Y4)/157 -> 0.10191083 | AB4: =Y4/$Y$159 -> 0.0036036036 | AC4: =ABS(X4-$AE$12) -> 78 | AD4: =0.6745*(X4-$AE$12)/$AE$13 -> 1.349 | AE4: =MIN(AA:AA) -> 0.044585987
A5: 107 | B5: =COUNTIFS(工作表1!C:C,"=" & A5) -> 1 | C5: =ABS(A5-$H$14)/$H$17 -> 0.96080067 | D5: =COUNTIFS($B$2:$B$111,"<="&B5)/110 -> 0.090909091 | E5: =B5/$B$112 -> 0.0011709602 | F5: =ABS(A5-$H$11) -> 52.5 | G5: =0.6745*(A5-$H$11)/$H$12 -> 1.2876818 | H5: =MAX(E:E) -> 1 | J5: 78 | K5: =COUNTIFS(工作表1!D:D,"=" & J5)/24094 -> 8.3008218e-05 | M5: =COUNTIFS($K$2:$K$63,">="&K5)/62 -> 0.9516129 | N5: =K5/$K$64 -> 0.0017064846 | O5: =0.6745*(J5-23)/10 -> 3.70975 | P5: =MAX(N:N) -> 1 | R5: 182 | S5: =COUNTIFS(工作表1!E:E,"=" & R5)/24094 -> 0.00012451233 | T5: =COUNTIFS($S$2:$S$93,">="&S5)/92 -> 0.93478261 | U5: =S5/$S$94 -> 0.002566296 | V5: =0.6745*(R5-40)/9 -> 10.642111 | W5: =MAX(U:U) -> 1 | X5: 155 | Y5: =COUNTIFS(工作表1!F:F,"=" & X5) -> 2 | Z5: =ABS(X5-$AE$15)/$AE$18 -> 0.98399477 | AA5: =COUNTIFS($Y$2:$Y$158,"<="&Y5)/157 -> 0.10191083 | AB5: =Y5/$Y$159 -> 0.0036036036 | AC5: =ABS(X5-$AE$12) -> 77 | AD5: =0.6745*(X5-$AE$12)/$AE$13 -> 1.3317051 | AE5: =MAX(AB:AB) -> 1
A6: 106 | B6: =COUNTIFS(工作表1!C:C,"=" & A6) -> 1 | C6: =ABS(A6-$H$14)/$H$17 -> 0.94245204 | D6: =COUNTIFS($B$2:$B$111,"<="&B6)/110 -> 0.090909091 | E6: =B6/$B$112 -> 0.0011709602 | F6: =ABS(A6-$H$11) -> 51.5 | G6: =0.6745*(A6-$H$11)/$H$12 -> 1.2631545 | H6: =MIN(E:E) -> 0.0011709602 | J6: 77 | K6: =COUNTIFS(工作表1!D:D,"=" & J6)/24094 -> 0.00016601644 | M6: =COUNTIFS($K$2:$K$63,">="&K6)/62 -> 0.88709677 | N6: =K6/$K$64 -> 0.0034129693 | O6: =0.6745*(J6-23)/10 -> 3.6423 | P6: =MIN(N:N) -> 0.00085324232 | R6: 177 | S6: =COUNTIFS(工作表1!E:E,"=" & R6)/24094 -> 0.00012451233 | T6: =COUNTIFS($S$2:$S$93,">="&S6)/92 -> 0.93478261 | U6: =S6/$S$94 -> 0.002566296 | V6: =0.6745*(R6-40)/9 -> 10.267389 | W6: =MIN(U:U) -> 0.00085543199 | X6: 154 | Y6: =COUNTIFS(工作表1!F:F,"=" & X6) -> 2 | Z6: =ABS(X6-$AE$15)/$AE$18 -> 0.97117426 | AA6: =COUNTIFS($Y$2:$Y$158,"<="&Y6)/157 -> 0.10191083 | AB6: =Y6/$Y$159 -> 0.0036036036 | AC6: =ABS(X6-$AE$12) -> 76 | AD6: =0.6745*(X6-$AE$12)/$AE$13 -> 1.3144103 | AE6: =MIN(AB:AB) -> 0.0018018018
A7: 105 | B7: =COUNTIFS(工作表1!C:C,"=" & A7) -> 1 | C7: =ABS(A7-$H$14)/$H$17 -> 0.92410342 | D7: =COUNTIFS($B$2:$B$111,"<="&B7)/110 -> 0.090909091 | E7: =B7/$B$112 -> 0.0011709602 | F7: =ABS(A7-$H$11) -> 50.5 | G7: =0.6745*(A7-$H$11)/$H$12 -> 1.2386273 | H7: =MAX(G:G) -> 1.4348455 | J7: 76 | K7: =COUNTIFS(工作表1!D:D,"=" & J7)/24094 -> 4.1504109e-05 | M7: =COUNTIFS($K$2:$K$63,">="&K7)/62 -> 1 | N7: =K7/$K$64 -> 0.00085324232 | O7: =0.6745*(J7-23)/10 -> 3.57485 | P7: =MAX(O:O) -> 5.2611 | R7: 174 | S7: =COUNTIFS(工作表1!E:E,"=" & R7)/24094 -> 0.00012451233 | T7: =COUNTIFS($S$2:$S$93,">="&S7)/92 -> 0.93478261 | U7: =S7/$S$94 -> 0.002566296 | V7: =0.6745*(R7-40)/9 -> 10.042556 | W7: =MAX(V:V) -> 12.141 | X7: 152 | Y7: =COUNTIFS(工作表1!F:F,"=" & X7) -> 2 | Z7: =ABS(X7-$AE$15)/$AE$18 -> 0.94553324 | AA7: =COUNTIFS($Y$2:$Y$158,"<="&Y7)/157 -> 0.10191083 | AB7: =Y7/$Y$159 -> 0.0036036036 | AC7: =ABS(X7-$AE$12) -> 74 | AD7: =0.6745*(X7-$AE$12)/$AE$13 -> 1.2798205 | AE7: =MAX(AD:AD) -> 1.5738333
A8: 104 | B8: =COUNTIFS(工作表1!C:C,"=" & A8) -> 4 | C8: =ABS(A8-$H$14)/$H$17 -> 0.9057548 | D8: =COUNTIFS($B$2:$B$111,"<="&B8)/110 -> 0.18181818 | E8: =B8/$B$112 -> 0.0046838407 | F8: =ABS(A8-$H$11) -> 49.5 | G8: =0.6745*(A8-$H$11)/$H$12 -> 1.2141 | H8: =MIN(G:G) -> -1.3367364 | J8: 75 | K8: =COUNTIFS(工作表1!D:D,"=" & J8)/24094 -> 4.1504109e-05 | M8: =COUNTIFS($K$2:$K$63,">="&K8)/62 -> 1 | N8: =K8/$K$64 -> 0.00085324232 | O8: =0.6745*(J8-23)/10 -> 3.5074 | P8: =MIN(O:O) -> -1.55135 | R8: 169 | S8: =COUNTIFS(工作表1!E:E,"=" & R8)/24094 -> 4.1504109e-05 | T8: =COUNTIFS($S$2:$S$93,">="&S8)/92 -> 1 | U8: =S8/$S$94 -> 0.00085543199 | V8: =0.6745*(R8-40)/9 -> 9.6678333 | W8: =MIN(V:V) -> -2.8478889 | X8: 151 | Y8: =COUNTIFS(工作表1!F:F,"=" & X8) -> 2 | Z8: =ABS(X8-$AE$15)/$AE$18 -> 0.93271272 | AA8: =COUNTIFS($Y$2:$Y$158,"<="&Y8)/157 -> 0.10191083 | AB8: =Y8/$Y$159 -> 0.0036036036 | AC8: =ABS(X8-$AE$12) -> 73 | AD8: =0.6745*(X8-$AE$12)/$AE$13 -> 1.2625256 | AE8: =MIN(AD:AD) -> -1.349
A9: 103 | B9: =COUNTIFS(工作表1!C:C,"=" & A9) -> 1 | C9: =ABS(A9-$H$14)/$H$17 -> 0.88740617 | D9: =COUNTIFS($B$2:$B$111,"<="&B9)/110 -> 0.090909091 | E9: =B9/$B$112 -> 0.0011709602 | F9: =ABS(A9-$H$11) -> 48.5 | G9: =0.6745*(A9-$H$11)/$H$12 -> 1.1895727 | H9: =MAX(B2:B111) -> 854 | J9: 74 | K9: =COUNTIFS(工作表1!D:D,"=" & J9)/24094 -> 0.00020752054 | M9: =COUNTIFS($K$2:$K$63,">="&K9)/62 -> 0.85483871 | N9: =K9/$K$64 -> 0.0042662116 | O9: =0.6745*(J9-23)/10 -> 3.43995 | P9: =MAX(K2:K63) -> 0.048642816 | R9: 166 | S9: =COUNTIFS(工作表1!E:E,"=" & R9)/24094 -> 0.00029052876 | T9: =COUNTIFS($S$2:$S$93,">="&S9)/92 -> 0.90217391 | U9: =S9/$S$94 -> 0.005988024 | V9: =0.6745*(R9-40)/9 -> 9.443 | X9: 150 | Y9: =COUNTIFS(工作表1!F:F,"=" & X9) -> 1 | Z9: =ABS(X9-$AE$15)/$AE$18 -> 0.91989221 | AA9: =COUNTIFS($Y$2:$Y$158,"<="&Y9)/157 -> 0.044585987 | AB9: =Y9/$Y$159 -> 0.0018018018 | AC9: =ABS(X9-$AE$12) -> 72 | AD9: =0.6745*(X9-$AE$12)/$AE$13 -> 1.2452308 | AE9: =MAX(Y2:Y158) -> 555
A10: 102 | B10: =COUNTIFS(工作表1!C:C,"=" & A10) -> 1 | C10: =ABS(A10-$H$14)/$H$17 -> 0.86905755 | D10: =COUNTIFS($B$2:$B$111,"<="&B10)/110 -> 0.090909091 | E10: =B10/$B$112 -> 0.0011709602 | F10: =ABS(A10-$H$11) -> 47.5 | G10: =0.6745*(A10-$H$11)/$H$12 -> 1.1650455 | J10: 73 | K10: =COUNTIFS(工作表1!D:D,"=" & J10)/24094 -> 8.3008218e-05 | M10: =COUNTIFS($K$2:$K$63,">="&K10)/62 -> 0.9516129 | N10: =K10/$K$64 -> 0.0017064846 | O10: =0.6745*(J10-23)/10 -> 3.3725 | R10: 164 | S10: =COUNTIFS(工作表1!E:E,"=" & R10)/24094 -> 0.00029052876 | T10: =COUNTIFS($S$2:$S$93,">="&S10)/92 -> 0.90217391 | U10: =S10/$S$94 -> 0.005988024 | V10: =0.6745*(R10-40)/9 -> 9.2931111 | X10: 149 | Y10: =COUNTIFS(工作表1!F:F,"=" & X10) -> 4 | Z10: =ABS(X10-$AE$15)/$AE$18 -> 0.9070717 | AA10: =COUNTIFS($Y$2:$Y$158,"<="&Y10)/157 -> 0.15286624 | AB10: =Y10/$Y$159 -> 0.0072072072 | AC10: =ABS(X10-$AE$12) -> 71 | AD10: =0.6745*(X10-$AE$12)/$AE$13 -> 1.2279359
A11: 101 | B11: =COUNTIFS(工作表1!C:C,"=" & A11) -> 1 | C11: =ABS(A11-$H$14)/$H$17 -> 0.85070892 | D11: =COUNTIFS($B$2:$B$111,"<="&B11)/110 -> 0.090909091 | E11: =B11/$B$112 -> 0.0011709602 | F11: =ABS(A11-$H$11) -> 46.5 | G11: =0.6745*(A11-$H$11)/$H$12 -> 1.1405182 | H11: =MEDIAN(A2:A111) -> 54.5 | J11: 72 | K11: =COUNTIFS(工作表1!D:D,"=" & J11)/24094 -> 0.00041504109 | M11: =COUNTIFS($K$2:$K$63,">="&K11)/62 -> 0.82258065 | N11: =K11/$K$64 -> 0.0085324232 | O11: =0.6745*(J11-23)/10 -> 3.30505 | R11: 161 | S11: =COUNTIFS(工作表1!E:E,"=" & R11)/24094 -> 0.00053955342 | T11: =COUNTIFS($S$2:$S$93,">="&S11)/92 -> 0.81521739 | U11: =S11/$S$94 -> 0.011120616 | V11: =0.6745*(R11-40)/9 -> 9.0682778 | X11: 148 | Y11: =COUNTIFS(工作表1!F:F,"=" & X11) -> 1 | Z11: =ABS(X11-$AE$15)/$AE$18 -> 0.89425118 | AA11: =COUNTIFS($Y$2:$Y$158,"<="&Y11)/157 -> 0.044585987 | AB11: =Y11/$Y$159 -> 0.0018018018 | AC11: =ABS(X11-$AE$12) -> 70 | AD11: =0.6745*(X11-$AE$12)/$AE$13 -> 1.210641
A12: 100 | B12: =COUNTIFS(工作表1!C:C,"=" & A12) -> 1 | C12: =ABS(A12-$H$14)/$H$17 -> 0.8323603 | D12: =COUNTIFS($B$2:$B$111,"<="&B12)/110 -> 0.090909091 | E12: =B12/$B$112 -> 0.0011709602 | F12: =ABS(A12-$H$11) -> 45.5 | G12: =0.6745*(A12-$H$11)/$H$12 -> 1.1159909 | H12: =MEDIAN(F2:F111) -> 27.5 | J12: 71 | K12: =COUNTIFS(工作表1!D:D,"=" & J12)/24094 -> 0.00012451233 | M12: =COUNTIFS($K$2:$K$63,">="&K12)/62 -> 0.91935484 | N12: =K12/$K$64 -> 0.002559727 | O12: =0.6745*(J12-23)/10 -> 3.2376 | R12: 159 | S12: =COUNTIFS(工作表1!E:E,"=" & R12)/24094 -> 0.00041504109 | T12: =COUNTIFS($S$2:$S$93,">="&S12)/92 -> 0.85869565 | U12: =S12/$S$94 -> 0.0085543199 | V12: =0.6745*(R12-40)/9 -> 8.9183889 | X12: 147 | Y12: =COUNTIFS(工作表1!F:F,"=" & X12) -> 1 | Z12: =ABS(X12-$AE$15)/$AE$18 -> 0.88143067 | AA12: =COUNTIFS($Y$2:$Y$158,"<="&Y12)/157 -> 0.044585987 | AB12: =Y12/$Y$159 -> 0.0018018018 | AC12: =ABS(X12-$AE$12) -> 69 | AD12: =0.6745*(X12-$AE$12)/$AE$13 -> 1.1933462 | AE12: =MEDIAN(X2:X158) -> 78
A13: 99 | B13: =COUNTIFS(工作表1!C:C,"=" & A13) -> 2 | C13: =ABS(A13-$H$14)/$H$17 -> 0.81401168 | D13: =COUNTIFS($B$2:$B$111,"<="&B13)/110 -> 0.13636364 | E13: =B13/$B$112 -> 0.0023419204 | F13: =ABS(A13-$H$11) -> 44.5 | G13: =0.6745*(A13-$H$11)/$H$12 -> 1.0914636 | J13: 70 | K13: =COUNTIFS(工作表1!D:D,"=" & J13)/24094 -> 0.00029052876 | M13: =COUNTIFS($K$2:$K$63,">="&K13)/62 -> 0.83870968 | N13: =K13/$K$64 -> 0.0059726962 | O13: =0.6745*(J13-23)/10 -> 3.17015 | R13: 156 | S13: =COUNTIFS(工作表1!E:E,"=" & R13)/24094 -> 0.00041504109 | T13: =COUNTIFS($S$2:$S$93,">="&S13)/92 -> 0.85869565 | U13: =S13/$S$94 -> 0.0085543199 | V13: =0.6745*(R13-40)/9 -> 8.6935556 | X13: 146 | Y13: =COUNTIFS(工作表1!F:F,"=" & X13) -> 3 | Z13: =ABS(X13-$AE$15)/$AE$18 -> 0.86861016 | AA13: =COUNTIFS($Y$2:$Y$158,"<="&Y13)/157 -> 0.12738854 | AB13: =Y13/$Y$159 -> 0.0054054054 | AC13: =ABS(X13-$AE$12) -> 68 | AD13: =0.6745*(X13-$AE$12)/$AE$13 -> 1.1760513 | AE13: =MEDIAN(AC2:AC158) -> 39
A14: 97 | B14: =COUNTIFS(工作表1!C:C,"=" & A14) -> 3 | C14: =ABS(A14-$H$14)/$H$17 -> 0.77731443 | D14: =COUNTIFS($B$2:$B$111,"<="&B14)/110 -> 0.16363636 | E14: =B14/$B$112 -> 0.0035128806 | F14: =ABS(A14-$H$11) -> 42.5 | G14: =0.6745*(A14-$H$11)/$H$12 -> 1.0424091 | H14: =AVERAGE(A2:A111) -> 54.636364 | J14: 69 | K14: =COUNTIFS(工作表1!D:D,"=" & J14)/24094 -> 0.0004565452 | M14: =COUNTIFS($K$2:$K$63,">="&K14)/62 -> 0.80645161 | N14: =K14/$K$64 -> 0.0093856655 | O14: =0.6745*(J14-23)/10 -> 3.1027 | R14: 154 | S14: =COUNTIFS(工作表1!E:E,"=" & R14)/24094 -> 0.0004565452 | T14: =COUNTIFS($S$2:$S$93,">="&S14)/92 -> 0.83695652 | U14: =S14/$S$94 -> 0.0094097519 | V14: =0.6745*(R14-40)/9 -> 8.5436667 | X14: 145 | Y14: =COUNTIFS(工作表1!F:F,"=" & X14) -> 3 | Z14: =ABS(X14-$AE$15)/$AE$18 -> 0.85578965 | AA14: =COUNTIFS($Y$2:$Y$158,"<="&Y14)/157 -> 0.12738854 | AB14: =Y14/$Y$159 -> 0.0054054054 | AC14: =ABS(X14-$AE$12) -> 67 | AD14: =0.6745*(X14-$AE$12)/$AE$13 -> 1.1587564
A15: 96 | B15: =COUNTIFS(工作表1!C:C,"=" & A15) -> 1 | C15: =ABS(A15-$H$14)/$H$17 -> 0.7589658 | D15: =COUNTIFS($B$2:$B$111,"<="&B15)/110 -> 0.090909091 | E15: =B15/$B$112 -> 0.0011709602 | F15: =ABS(A15-$H$11) -> 41.5 | G15: =0.6745*(A15-$H$11)/$H$12 -> 1.0178818 | H15: =_xlfn.STDEV.P(A2:A111) -> 31.970932 | J15: 68 | K15: =COUNTIFS(工作表1!D:D,"=" & J15)/24094 -> 0.00062256163 | M15: =COUNTIFS($K$2:$K$63,">="&K15)/62 -> 0.77419355 | N15: =K15/$K$64 -> 0.012798635 | O15: =0.6745*(J15-23)/10 -> 3.03525 | R15: 151 | S15: =COUNTIFS(工作表1!E:E,"=" & R15)/24094 -> 0.0009545945 | T15: =COUNTIFS($S$2:$S$93,">="&S15)/92 -> 0.76086957 | U15: =S15/$S$94 -> 0.019674936 | V15: =0.6745*(R15-40)/9 -> 8.3188333 | X15: 144 | Y15: =COUNTIFS(工作表1!F:F,"=" & X15) -> 2 | Z15: =ABS(X15-$AE$15)/$AE$18 -> 0.84296913 | AA15: =COUNTIFS($Y$2:$Y$158,"<="&Y15)/157 -> 0.10191083 | AB15: =Y15/$Y$159 -> 0.0036036036 | AC15: =ABS(X15-$AE$12) -> 66 | AD15: =0.6745*(X15-$AE$12)/$AE$13 -> 1.1414615 | AE15: =AVERAGE(X2:X158) -> 78.248408
A16: 95 | B16: =COUNTIFS(工作表1!C:C,"=" & A16) -> 2 | C16: =ABS(A16-$H$14)/$H$17 -> 0.74061718 | D16: =COUNTIFS($B$2:$B$111,"<="&B16)/110 -> 0.13636364 | E16: =B16/$B$112 -> 0.0023419204 | F16: =ABS(A16-$H$11) -> 40.5 | G16: =0.6745*(A16-$H$11)/$H$12 -> 0.99335455 | J16: 67 | K16: =COUNTIFS(工作表1!D:D,"=" & J16)/24094 -> 0.0014111397 | M16: =COUNTIFS($K$2:$K$63,">="&K16)/62 -> 0.74193548 | N16: =K16/$K$64 -> 0.029010239 | O16: =0.6745*(J16-23)/10 -> 2.9678 | R16: 150 | S16: =COUNTIFS(工作表1!E:E,"=" & R16)/24094 -> 0.00066406574 | T16: =COUNTIFS($S$2:$S$93,">="&S16)/92 -> 0.80434783 | U16: =S16/$S$94 -> 0.013686912 | V16: =0.6745*(R16-40)/9 -> 8.2438889 | X16: 143 | Y16: =COUNTIFS(工作表1!F:F,"=" & X16) -> 1 | Z16: =ABS(X16-$AE$15)/$AE$18 -> 0.83014862 | AA16: =COUNTIFS($Y$2:$Y$158,"<="&Y16)/157 -> 0.044585987 | AB16: =Y16/$Y$159 -> 0.0018018018 | AC16: =ABS(X16-$AE$12) -> 65 | AD16: =0.6745*(X16-$AE$12)/$AE$13 -> 1.1241667 | AE16: =_xlfn.STDEV.P(X2:X158) -> 45.74906
A17: 94 | B17: =COUNTIFS(工作表1!C:C,"=" & A17) -> 3 | C17: =ABS(A17-$H$14)/$H$17 -> 0.72226856 | D17: =COUNTIFS($B$2:$B$111,"<="&B17)/110 -> 0.16363636 | E17: =B17/$B$112 -> 0.0035128806 | F17: =ABS(A17-$H$11) -> 39.5 | G17: =0.6745*(A17-$H$11)/$H$12 -> 0.96882727 | H17: =QUARTILE(A2:A111,3)-QUARTILE(A2:A111,1) -> 54.5 | J17: 66 | K17: =COUNTIFS(工作表1!D:D,"=" & J17)/24094 -> 0.00053955342 | M17: =COUNTIFS($K$2:$K$63,">="&K17)/62 -> 0.79032258 | N17: =K17/$K$64 -> 0.01109215 | O17: =0.6745*(J17-23)/10 -> 2.90035 | R17: 146 | S17: =COUNTIFS(工作表1!E:E,"=" & R17)/24094 -> 0.00078857807 | T17: =COUNTIFS($S$2:$S$93,">="&S17)/92 -> 0.79347826 | U17: =S17/$S$94 -> 0.016253208 | V17: =0.6745*(R17-40)/9 -> 7.9441111 | X17: 141 | Y17: =COUNTIFS(工作表1!F:F,"=" & X17) -> 2 | Z17: =ABS(X17-$AE$15)/$AE$18 -> 0.80450759 | AA17: =COUNTIFS($Y$2:$Y$158,"<="&Y17)/157 -> 0.10191083 | AB17: =Y17/$Y$159 -> 0.0036036036 | AC17: =ABS(X17-$AE$12) -> 63 | AD17: =0.6745*(X17-$AE$12)/$AE$13 -> 1.0895769
A18: 93 | B18: =COUNTIFS(工作表1!C:C,"=" & A18) -> 2 | C18: =ABS(A18-$H$14)/$H$17 -> 0.70391993 | D18: =COUNTIFS($B$2:$B$111,"<="&B18)/110 -> 0.13636364 | E18: =B18/$B$112 -> 0.0023419204 | F18: =ABS(A18-$H$11) -> 38.5 | G18: =0.6745*(A18-$H$11)/$H$12 -> 0.9443 | J18: 65 | K18: =COUNTIFS(工作表1!D:D,"=" & J18)/24094 -> 0.00078857807 | M18: =COUNTIFS($K$2:$K$63,">="&K18)/62 -> 0.75806452 | N18: =K18/$K$64 -> 0.016211604 | O18: =0.6745*(J18-23)/10 -> 2.8329 | R18: 143 | S18: =COUNTIFS(工作表1!E:E,"=" & R18)/24094 -> 0.0010376027 | T18: =COUNTIFS($S$2:$S$93,">="&S18)/92 -> 0.75 | U18: =S18/$S$94 -> 0.0213858 | V18: =0.6745*(R18-40)/9 -> 7.7192778 | X18: 140 | Y18: =COUNTIFS(工作表1!F:F,"=" & X18) -> 4 | Z18: =ABS(X18-$AE$15)/$AE$18 -> 0.79168708 | AA18: =COUNTIFS($Y$2:$Y$158,"<="&Y18)/157 -> 0.15286624 | AB18: =Y18/$Y$159 -> 0.0072072072 | AC18: =ABS(X18-$AE$12) -> 62 | AD18: =0.6745*(X18-$AE$12)/$AE$13 -> 1.0722821 | AE18: =QUARTILE(X2:X158,3)-QUARTILE(X2:X158,1) -> 78
A19: 92 | B19: =COUNTIFS(工作表1!C:C,"=" & A19) -> 7 | C19: =ABS(A19-$H$14)/$H$17 -> 0.68557131 | D19: =COUNTIFS($B$2:$B$111,"<="&B19)/110 -> 0.21818182 | E19: =B19/$B$112 -> 0.0081967213 | F19: =ABS(A19-$H$11) -> 37.5 | G19: =0.6745*(A19-$H$11)/$H$12 -> 0.91977273 | J19: 64 | K19: =COUNTIFS(工作表1!D:D,"=" & J19)/24094 -> 0.0021582137 | M19: =COUNTIFS($K$2:$K$63,">="&K19)/62 -> 0.69354839 | N19: =K19/$K$64 -> 0.044368601 | O19: =0.6745*(J19-23)/10 -> 2.76545 | R19: 140 | S19: =COUNTIFS(工作表1!E:E,"=" & R19)/24094 -> 0.0011206109 | T19: =COUNTIFS($S$2:$S$93,">="&S19)/92 -> 0.72826087 | U19: =S19/$S$94 -> 0.023096664 | V19: =0.6745*(R19-40)/9 -> 7.4944444 | X19: 139 | Y19: =COUNTIFS(工作表1!F:F,"=" & X19) -> 5 | Z19: =ABS(X19-$AE$15)/$AE$18 -> 0.77886657 | AA19: =COUNTIFS($Y$2:$Y$158,"<="&Y19)/157 -> 0.15923567 | AB19: =Y19/$Y$159 -> 0.009009009 | AC19: =ABS(X19-$AE$12) -> 61 | AD19: =0.6745*(X19-$AE$12)/$AE$13 -> 1.0549872
A20: 91 | B20: =COUNTIFS(工作表1!C:C,"=" & A20) -> 2 | C20: =ABS(A20-$H$14)/$H$17 -> 0.66722269 | D20: =COUNTIFS($B$2:$B$111,"<="&B20)/110 -> 0.13636364 | E20: =B20/$B$112 -> 0.0023419204 | F20: =ABS(A20-$H$11) -> 36.5 | G20: =0.6745*(A20-$H$11)/$H$12 -> 0.89524545 | J20: 63 | K20: =COUNTIFS(工作表1!D:D,"=" & J20)/24094 -> 0.001535652 | M20: =COUNTIFS($K$2:$K$63,">="&K20)/62 -> 0.72580645 | N20: =K20/$K$64 -> 0.031569966 | O20: =0.6745*(J20-23)/10 -> 2.698 | R20: 136 | S20: =COUNTIFS(工作表1!E:E,"=" & R20)/24094 -> 0.0010376027 | T20: =COUNTIFS($S$2:$S$93,">="&S20)/92 -> 0.75 | U20: =S20/$S$94 -> 0.0213858 | V20: =0.6745*(R20-40)/9 -> 7.1946667 | X20: 138 | Y20: =COUNTIFS(工作表1!F:F,"=" & X20) -> 3 | Z20: =ABS(X20-$AE$15)/$AE$18 -> 0.76604606 | AA20: =COUNTIFS($Y$2:$Y$158,"<="&Y20)/157 -> 0.12738854 | AB20: =Y20/$Y$159 -> 0.0054054054 | AC20: =ABS(X20-$AE$12) -> 60 | AD20: =0.6745*(X20-$AE$12)/$AE$13 -> 1.0376923
A21: 90 | B21: =COUNTIFS(工作表1!C:C,"=" & A21) -> 5 | C21: =ABS(A21-$H$14)/$H$17 -> 0.64887406 | D21: =COUNTIFS($B$2:$B$111,"<="&B21)/110 -> 0.19090909 | E21: =B21/$B$112 -> 0.0058548009 | F21: =ABS(A21-$H$11) -> 35.5 | G21: =0.6745*(A21-$H$11)/$H$12 -> 0.87071818 | J21: 62 | K21: =COUNTIFS(工作表1!D:D,"=" & J21)/24094 -> 0.0022412219 | M21: =COUNTIFS($K$2:$K$63,">="&K21)/62 -> 0.67741935 | N21: =K21/$K$64 -> 0.046075085 | O21: =0.6745*(J21-23)/10 -> 2.63055 | R21: 132 | S21: =COUNTIFS(工作表1!E:E,"=" & R21)/24094 -> 0.0012451233 | T21: =COUNTIFS($S$2:$S$93,">="&S21)/92 -> 0.7173913 | U21: =S21/$S$94 -> 0.02566296 | V21: =0.6745*(R21-40)/9 -> 6.8948889 | X21: 137 | Y21: =COUNTIFS(工作表1!F:F,"=" & X21) -> 2 | Z21: =ABS(X21-$AE$15)/$AE$18 -> 0.75322554 | AA21: =COUNTIFS($Y$2:$Y$158,"<="&Y21)/157 -> 0.10191083 | AB21: =Y21/$Y$159 -> 0.0036036036 | AC21: =ABS(X21-$AE$12) -> 59 | AD21: =0.6745*(X21-$AE$12)/$AE$13 -> 1.0203974
A22: 89 | B22: =COUNTIFS(工作表1!C:C,"=" & A22) -> 3 | C22: =ABS(A22-$H$14)/$H$17 -> 0.63052544 | D22: =COUNTIFS($B$2:$B$111,"<="&B22)/110 -> 0.16363636 | E22: =B22/$B$112 -> 0.0035128806 | F22: =ABS(A22-$H$11) -> 34.5 | G22: =0.6745*(A22-$H$11)/$H$12 -> 0.84619091 | J22: 61 | K22: =COUNTIFS(工作表1!D:D,"=" & J22)/24094 -> 0.001909189 | M22: =COUNTIFS($K$2:$K$63,">="&K22)/62 -> 0.70967742 | N22: =K22/$K$64 -> 0.039249147 | O22: =0.6745*(J22-23)/10 -> 2.5631 | R22: 129 | S22: =COUNTIFS(工作表1!E:E,"=" & R22)/24094 -> 0.0023242301 | T22: =COUNTIFS($S$2:$S$93,">="&S22)/92 -> 0.66304348 | U22: =S22/$S$94 -> 0.047904192 | V22: =0.6745*(R22-40)/9 -> 6.6700556 | X22: 136 | Y22: =COUNTIFS(工作表1!F:F,"=" & X22) -> 1 | Z22: =ABS(X22-$AE$15)/$AE$18 -> 0.74040503 | AA22: =COUNTIFS($Y$2:$Y$158,"<="&Y22)/157 -> 0.044585987 | AB22: =Y22/$Y$159 -> 0.0018018018 | AC22: =ABS(X22-$AE$12) -> 58 | AD22: =0.6745*(X22-$AE$12)/$AE$13 -> 1.0031026
A23: 88 | B23: =COUNTIFS(工作表1!C:C,"=" & A23) -> 8 | C23: =ABS(A23-$H$14)/$H$17 -> 0.61217681 | D23: =COUNTIFS($B$2:$B$111,"<="&B23)/110 -> 0.23636364 | E23: =B23/$B$112 -> 0.0093676815 | F23: =ABS(A23-$H$11) -> 33.5 | G23: =0.6745*(A23-$H$11)/$H$12 -> 0.82166364 | J23: 60 | K23: =COUNTIFS(工作表1!D:D,"=" & J23)/24094 -> 0.0043994355 | M23: =COUNTIFS($K$2:$K$63,">="&K23)/62 -> 0.61290323 | N23: =K23/$K$64 -> 0.090443686 | O23: =0.6745*(J23-23)/10 -> 2.49565 | R23: 126 | S23: =COUNTIFS(工作表1!E:E,"=" & R23)/24094 -> 0.0021997178 | T23: =COUNTIFS($S$2:$S$93,">="&S23)/92 -> 0.67391304 | U23: =S23/$S$94 -> 0.045337896 | V23: =0.6745*(R23-40)/9 -> 6.4452222 | X23: 135 | Y23: =COUNTIFS(工作表1!F:F,"=" & X23) -> 4 | Z23: =ABS(X23-$AE$15)/$AE$18 -> 0.72758452 | AA23: =COUNTIFS($Y$2:$Y$158,"<="&Y23)/157 -> 0.15286624 | AB23: =Y23/$Y$159 -> 0.0072072072 | AC23: =ABS(X23-$AE$12) -> 57 | AD23: =0.6745*(X23-$AE$12)/$AE$13 -> 0.98580769
A24: 87 | B24: =COUNTIFS(工作表1!C:C,"=" & A24) -> 4 | C24: =ABS(A24-$H$14)/$H$17 -> 0.59382819 | D24: =COUNTIFS($B$2:$B$111,"<="&B24)/110 -> 0.18181818 | E24: =B24/$B$112 -> 0.0046838407 | F24: =ABS(A24-$H$11) -> 32.5 | G24: =0.6745*(A24-$H$11)/$H$12 -> 0.79713636 | J24: 59 | K24: =COUNTIFS(工作表1!D:D,"=" & J24)/24094 -> 0.0023657342 | M24: =COUNTIFS($K$2:$K$63,">="&K24)/62 -> 0.64516129 | N24: =K24/$K$64 -> 0.048634812 | O24: =0.6745*(J24-23)/10 -> 2.4282 | R24: 122 | S24: =COUNTIFS(工作表1!E:E,"=" & R24)/24094 -> 0.0020337013 | T24: =COUNTIFS($S$2:$S$93,">="&S24)/92 -> 0.68478261 | U24: =S24/$S$94 -> 0.041916168 | V24: =0.6745*(R24-40)/9 -> 6.1454444 | X24: 134 | Y24: =COUNTIFS(工作表1!F:F,"=" & X24) -> 3 | Z24: =ABS(X24-$AE$15)/$AE$18 -> 0.714764 | AA24: =COUNTIFS($Y$2:$Y$158,"<="&Y24)/157 -> 0.12738854 | AB24: =Y24/$Y$159 -> 0.0054054054 | AC24: =ABS(X24-$AE$12) -> 56 | AD24: =0.6745*(X24-$AE$12)/$AE$13 -> 0.96851282
A25: 86 | B25: =COUNTIFS(工作表1!C:C,"=" & A25) -> 8 | C25: =ABS(A25-$H$14)/$H$17 -> 0.57547957 | D25: =COUNTIFS($B$2:$B$111,"<="&B25)/110 -> 0.23636364 | E25: =B25/$B$112 -> 0.0093676815 | F25: =ABS(A25-$H$11) -> 31.5 | G25: =0.6745*(A25-$H$11)/$H$12 -> 0.77260909 | J25: 58 | K25: =COUNTIFS(工作表1!D:D,"=" & J25)/24094 -> 0.0027807753 | M25: =COUNTIFS($K$2:$K$63,">="&K25)/62 -> 0.62903226 | N25: =K25/$K$64 -> 0.057167235 | O25: =0.6745*(J25-23)/10 -> 2.36075 | R25: 118 | S25: =COUNTIFS(工作表1!E:E,"=" & R25)/24094 -> 0.0027807753 | T25: =COUNTIFS($S$2:$S$93,">="&S25)/92 -> 0.64130435 | U25: =S25/$S$94 -> 0.057313944 | V25: =0.6745*(R25-40)/9 -> 5.8456667 | X25: 133 | Y25: =COUNTIFS(工作表1!F:F,"=" & X25) -> 6 | Z25: =ABS(X25-$AE$15)/$AE$18 -> 0.70194349 | AA25: =COUNTIFS($Y$2:$Y$158,"<="&Y25)/157 -> 0.17834395 | AB25: =Y25/$Y$159 -> 0.010810811 | AC25: =ABS(X25-$AE$12) -> 55 | AD25: =0.6745*(X25-$AE$12)/$AE$13 -> 0.95121795
A26: 85 | B26: =COUNTIFS(工作表1!C:C,"=" & A26) -> 9 | C26: =ABS(A26-$H$14)/$H$17 -> 0.55713094 | D26: =COUNTIFS($B$2:$B$111,"<="&B26)/110 -> 0.26363636 | E26: =B26/$B$112 -> 0.010538642 | F26: =ABS(A26-$H$11) -> 30.5 | G26: =0.6745*(A26-$H$11)/$H$12 -> 0.74808182 | J26: 57 | K26: =COUNTIFS(工作表1!D:D,"=" & J26)/24094 -> 0.0063916328 | M26: =COUNTIFS($K$2:$K$63,">="&K26)/62 -> 0.56451613 | N26: =K26/$K$64 -> 0.13139932 | O26: =0.6745*(J26-23)/10 -> 2.2933 | R26: 115 | S26: =COUNTIFS(工作表1!E:E,"=" & R26)/24094 -> 0.0027807753 | T26: =COUNTIFS($S$2:$S$93,">="&S26)/92 -> 0.64130435 | U26: =S26/$S$94 -> 0.057313944 | V26: =0.6745*(R26-40)/9 -> 5.6208333 | X26: 132 | Y26: =COUNTIFS(工作表1!F:F,"=" & X26) -> 6 | Z26: =ABS(X26-$AE$15)/$AE$18 -> 0.68912298 | AA26: =COUNTIFS($Y$2:$Y$158,"<="&Y26)/157 -> 0.17834395 | AB26: =Y26/$Y$159 -> 0.010810811 | AC26: =ABS(X26-$AE$12) -> 54 | AD26: =0.6745*(X26-$AE$12)/$AE$13 -> 0.93392308
A27: 84 | B27: =COUNTIFS(工作表1!C:C,"=" & A27) -> 7 | C27: =ABS(A27-$H$14)/$H$17 -> 0.53878232 | D27: =COUNTIFS($B$2:$B$111,"<="&B27)/110 -> 0.21818182 | E27: =B27/$B$112 -> 0.0081967213 | F27: =ABS(A27-$H$11) -> 29.5 | G27: =0.6745*(A27-$H$11)/$H$12 -> 0.72355455 | J27: 56 | K27: =COUNTIFS(工作表1!D:D,"=" & J27)/24094 -> 0.0043994355 | M27: =COUNTIFS($K$2:$K$63,">="&K27)/62 -> 0.61290323 | N27: =K27/$K$64 -> 0.090443686 | O27: =0.6745*(J27-23)/10 -> 2.22585 | R27: 112 | S27: =COUNTIFS(工作表1!E:E,"=" & R27)/24094 -> 0.0032373205 | T27: =COUNTIFS($S$2:$S$93,">="&S27)/92 -> 0.61956522 | U27: =S27/$S$94 -> 0.066723695 | V27: =0.6745*(R27-40)/9 -> 5.396 | X27: 131 | Y27: =COUNTIFS(工作表1!F:F,"=" & X27) -> 4 | Z27: =ABS(X27-$AE$15)/$AE$18 -> 0.67630247 | AA27: =COUNTIFS($Y$2:$Y$158,"<="&Y27)/157 -> 0.15286624 | AB27: =Y27/$Y$159 -> 0.0072072072 | AC27: =ABS(X27-$AE$12) -> 53 | AD27: =0.6745*(X27-$AE$12)/$AE$13 -> 0.91662821
A28: 83 | B28: =COUNTIFS(工作表1!C:C,"=" & A28) -> 6 | C28: =ABS(A28-$H$14)/$H$17 -> 0.52043369 | D28: =COUNTIFS($B$2:$B$111,"<="&B28)/110 -> 0.2 | E28: =B28/$B$112 -> 0.0070257611 | F28: =ABS(A28-$H$11) -> 28.5 | G28: =0.6745*(A28-$H$11)/$H$12 -> 0.69902727 | J28: 55 | K28: =COUNTIFS(工作表1!D:D,"=" & J28)/24094 -> 0.01141363 | M28: =COUNTIFS($K$2:$K$63,">="&K28)/62 -> 0.5 | N28: =K28/$K$64 -> 0.23464164 | O28: =0.6745*(J28-23)/10 -> 2.1584 | R28: 108 | S28: =COUNTIFS(工作表1!E:E,"=" & R28)/24094 -> 0.003818378 | T28: =COUNTIFS($S$2:$S$93,">="&S28)/92 -> 0.59782609 | U28: =S28/$S$94 -> 0.078699743 | V28: =0.6745*(R28-40)/9 -> 5.0962222 | X28: 130 | Y28: =COUNTIFS(工作表1!F:F,"=" & X28) -> 2 | Z28: =ABS(X28-$AE$15)/$AE$18 -> 0.66348195 | AA28: =COUNTIFS($Y$2:$Y$158,"<="&Y28)/157 -> 0.10191083 | AB28: =Y28/$Y$159 -> 0.0036036036 | AC28: =ABS(X28-$AE$12) -> 52 | AD28: =0.6745*(X28-$AE$12)/$AE$13 -> 0.89933333
A29: 82 | B29: =COUNTIFS(工作表1!C:C,"=" & A29) -> 9 | C29: =ABS(A29-$H$14)/$H$17 -> 0.50208507 | D29: =COUNTIFS($B$2:$B$111,"<="&B29)/110 -> 0.26363636 | E29: =B29/$B$112 -> 0.010538642 | F29: =ABS(A29-$H$11) -> 27.5 | G29: =0.6745*(A29-$H$11)/$H$12 -> 0.6745 | J29: 54 | K29: =COUNTIFS(工作表1!D:D,"=" & J29)/24094 -> 0.006101104 | M29: =COUNTIFS($K$2:$K$63,">="&K29)/62 -> 0.58064516 | N29: =K29/$K$64 -> 0.12542662 | O29: =0.6745*(J29-23)/10 -> 2.09095 | R29: 104 | S29: =COUNTIFS(工作表1!E:E,"=" & R29)/24094 -> 0.003818378 | T29: =COUNTIFS($S$2:$S$93,">="&S29)/92 -> 0.59782609 | U29: =S29/$S$94 -> 0.078699743 | V29: =0.6745*(R29-40)/9 -> 4.7964444 | X29: 129 | Y29: =COUNTIFS(工作表1!F:F,"=" & X29) -> 8 | Z29: =ABS(X29-$AE$15)/$AE$18 -> 0.65066144 | AA29: =COUNTIFS($Y$2:$Y$158,"<="&Y29)/157 -> 0.21019108 | AB29: =Y29/$Y$159 -> 0.014414414 | AC29: =ABS(X29-$AE$12) -> 51 | AD29: =0.6745*(X29-$AE$12)/$AE$13 -> 0.88203846
A30: 81 | B30: =COUNTIFS(工作表1!C:C,"=" & A30) -> 17 | C30: =ABS(A30-$H$14)/$H$17 -> 0.48373645 | D30: =COUNTIFS($B$2:$B$111,"<="&B30)/110 -> 0.29090909 | E30: =B30/$B$112 -> 0.019906323 | F30: =ABS(A30-$H$11) -> 26.5 | G30: =0.6745*(A30-$H$11)/$H$12 -> 0.64997273 | J30: 53 | K30: =COUNTIFS(工作表1!D:D,"=" & J30)/24094 -> 0.0066821615 | M30: =COUNTIFS($K$2:$K$63,">="&K30)/62 -> 0.5483871 | N30: =K30/$K$64 -> 0.13737201 | O30: =0.6745*(J30-23)/10 -> 2.0235 | R30: 101 | S30: =COUNTIFS(工作表1!E:E,"=" & R30)/24094 -> 0.0047729725 | T30: =COUNTIFS($S$2:$S$93,">="&S30)/92 -> 0.56521739 | U30: =S30/$S$94 -> 0.098374679 | V30: =0.6745*(R30-40)/9 -> 4.5716111 | X30: 128 | Y30: =COUNTIFS(工作表1!F:F,"=" & X30) -> 10 | Z30: =ABS(X30-$AE$15)/$AE$18 -> 0.63784093 | AA30: =COUNTIFS($Y$2:$Y$158,"<="&Y30)/157 -> 0.22929936 | AB30: =Y30/$Y$159 -> 0.018018018 | AC30: =ABS(X30-$AE$12) -> 50 | AD30: =0.6745*(X30-$AE$12)/$AE$13 -> 0.86474359
... A63: 48 | B63: =COUNTIFS(工作表1!C:C,"=" & A63) -> 210 | C63: =ABS(A63-$H$14)/$H$17 -> 0.12176814 | D63: =COUNTIFS($B$2:$B$111,"<="&B63)/110 -> 0.61818182 | E63: =B63/$B$112 -> 0.24590164 | F63: =ABS(A63-$H$11) -> 6.5 | G63: =0.6745*(A63-$H$11)/$H$12 -> -0.15942727 | J63: 0 | K63: =COUNTIFS(工作表1!D:D,"=" & J63)/24094 -> 0.002282726 | M63: =COUNTIFS($K$2:$K$63,">="&K63)/62 -> 0.66129032 | N63: =K63/$K$64 -> 0.046928328 | O63: =0.6745*(J63-23)/10 -> -1.55135 | R63: 34 | S63: =COUNTIFS(工作表1!E:E,"=" & R63)/24094 -> 0.024943969 | T63: =COUNTIFS($S$2:$S$93,">="&S63)/92 -> 0.15217391 | U63: =S63/$S$94 -> 0.51411463 | V63: =0.6745*(R63-40)/9 -> -0.44966667 | X63: 95 | Y63: =COUNTIFS(工作表1!F:F,"=" & X63) -> 61 | Z63: =ABS(X63-$AE$15)/$AE$18 -> 0.214764 | AA63: =COUNTIFS($Y$2:$Y$158,"<="&Y63)/157 -> 0.43949045 | AB63: =Y63/$Y$159 -> 0.10990991 | AC63: =ABS(X63-$AE$12) -> 17 | AD63: =0.6745*(X63-$AE$12)/$AE$13 -> 0.29401282
A64: 47 | B64: =COUNTIFS(工作表1!C:C,"=" & A64) -> 215 | C64: =ABS(A64-$H$14)/$H$17 -> 0.14011676 | D64: =COUNTIFS($B$2:$B$111,"<="&B64)/110 -> 0.63636364 | E64: =B64/$B$112 -> 0.25175644 | F64: =ABS(A64-$H$11) -> 7.5 | G64: =0.6745*(A64-$H$11)/$H$12 -> -0.18395455 | K64: =MAX(K2:K63) -> 0.048642816 | R64: 33 | S64: =COUNTIFS(工作表1!E:E,"=" & R64)/24094 -> 0.025359011 | T64: =COUNTIFS($S$2:$S$93,">="&S64)/92 -> 0.13043478 | U64: =S64/$S$94 -> 0.52266895 | V64: =0.6745*(R64-40)/9 -> -0.52461111 | X64: 94 | Y64: =COUNTIFS(工作表1!F:F,"=" & X64) -> 41 | Z64: =ABS(X64-$AE$15)/$AE$18 -> 0.20194349 | AA64: =COUNTIFS($Y$2:$Y$158,"<="&Y64)/157 -> 0.39490446 | AB64: =Y64/$Y$159 -> 0.073873874 | AC64: =ABS(X64-$AE$12) -> 16 | AD64: =0.6745*(X64-$AE$12)/$AE$13 -> 0.27671795
A65: 46 | B65: =COUNTIFS(工作表1!C:C,"=" & A65) -> 224 | C65: =ABS(A65-$H$14)/$H$17 -> 0.15846539 | D65: =COUNTIFS($B$2:$B$111,"<="&B65)/110 -> 0.64545455 | E65: =B65/$B$112 -> 0.26229508 | F65: =ABS(A65-$H$11) -> 8.5 | G65: =0.6745*(A65-$H$11)/$H$12 -> -0.20848182 | R65: 32 | S65: =COUNTIFS(工作表1!E:E,"=" & R65)/24094 -> 0.025981572 | T65: =COUNTIFS($S$2:$S$93,">="&S65)/92 -> 0.10869565 | U65: =S65/$S$94 -> 0.53550043 | V65: =0.6745*(R65-40)/9 -> -0.59955556 | X65: 93 | Y65: =COUNTIFS(工作表1!F:F,"=" & X65) -> 43 | Z65: =ABS(X65-$AE$15)/$AE$18 -> 0.18912298 | AA65: =COUNTIFS($Y$2:$Y$158,"<="&Y65)/157 -> 0.40764331 | AB65: =Y65/$Y$159 -> 0.077477477 | AC65: =ABS(X65-$AE$12) -> 15 | AD65: =0.6745*(X65-$AE$12)/$AE$13 -> 0.25942308
A66: 45 | B66: =COUNTIFS(工作表1!C:C,"=" & A66) -> 244 | C66: =ABS(A66-$H$14)/$H$17 -> 0.17681401 | D66: =COUNTIFS($B$2:$B$111,"<="&B66)/110 -> 0.65454545 | E66: =B66/$B$112 -> 0.28571429 | F66: =ABS(A66-$H$11) -> 9.5 | G66: =0.6745*(A66-$H$11)/$H$12 -> -0.23300909 | R66: 31 | S66: =COUNTIFS(工作表1!E:E,"=" & R66)/24094 -> 0.046899643 | T66: =COUNTIFS($S$2:$S$93,">="&S66)/92 -> 0.02173913 | U66: =S66/$S$94 -> 0.96663815 | V66: =0.6745*(R66-40)/9 -> -0.6745 | X66: 92 | Y66: =COUNTIFS(工作表1!F:F,"=" & X66) -> 48 | Z66: =ABS(X66-$AE$15)/$AE$18 -> 0.17630247 | AA66: =COUNTIFS($Y$2:$Y$158,"<="&Y66)/157 -> 0.42038217 | AB66: =Y66/$Y$159 -> 0.086486486 | AC66: =ABS(X66-$AE$12) -> 14 | AD66: =0.6745*(X66-$AE$12)/$AE$13 -> 0.24212821
